*** Starting uWSGI 2.0.18 (64bit) on [Wed Mar 13 16:33:57 2019] ***
compiled with version: 5.4.0 20160609 on 13 March 2019 08:00:41
os: Linux-4.4.0-142-generic #168-Ubuntu SMP Wed Jan 16 21:00:45 UTC 2019
nodename: iZwz98nqijeqfo9ffbtx0zZ
machine: x86_64
clock source: unix
detected number of CPU cores: 1
current working directory: /var/www/axf
writing pidfile to uwsgi.pid
detected binary path: /root/.virtualenvs/python3/bin/uwsgi
!!! no internal routing support, rebuild with pcre support !!!
uWSGI running as root, you can use --uid/--gid/--chroot options
*** WARNING: you are running uWSGI as root !!! (use the --uid flag) *** 
chdir() to /var/www/axf
*** WARNING: you are running uWSGI without its master process manager ***
your processes number limit is 3817
your memory page size is 4096 bytes
detected max file descriptor number: 65535
lock engine: pthread robust mutexes
thunder lock: disabled (you can enable it with --thunder-lock)
uWSGI http bound on 0.0.0.0:8000 fd 4
spawned uWSGI http 1 (pid: 21410)
uwsgi socket 0 bound to TCP address 127.0.0.1:34626 (port auto-assigned) fd 3
uWSGI running as root, you can use --uid/--gid/--chroot options
*** WARNING: you are running uWSGI as root !!! (use the --uid flag) *** 
Python version: 3.5.2 (default, Nov 12 2018, 13:43:14)  [GCC 5.4.0 20160609]
*** Python threads support is disabled. You can enable it with --enable-threads ***
Python main interpreter initialized at 0x25e25a0
uWSGI running as root, you can use --uid/--gid/--chroot options
*** WARNING: you are running uWSGI as root !!! (use the --uid flag) *** 
your server socket listen backlog is limited to 100 connections
your mercy for graceful operations on workers is 60 seconds
mapped 72904 bytes (71 KB) for 1 cores
*** Operational MODE: single process ***
WSGI app 0 (mountpoint='') ready in 1 seconds on interpreter 0x25e25a0 pid: 21409 (default app)
uWSGI running as root, you can use --uid/--gid/--chroot options
*** WARNING: you are running uWSGI as root !!! (use the --uid flag) *** 
*** uWSGI is running in multiple interpreter mode ***
spawned uWSGI worker 1 (and the only) (pid: 21409, cores: 1)
[pid: 21409|app: 0|req: 1/1] 113.87.160.176 () {36 vars in 645 bytes} [Wed Mar 13 16:38:39 2019] GET /axf/ => generated 21767 bytes in 72 msecs (HTTP/1.1 200) 3 headers in 111 bytes (1 switches on core 0)
[pid: 21409|app: 0|req: 2/2] 113.88.14.120 () {38 vars in 701 bytes} [Wed Mar 13 16:38:43 2019] GET /axf/mine/ => generated 5934 bytes in 14 msecs (HTTP/1.1 200) 4 headers in 124 bytes (1 switches on core 0)
Not Found: /static/mine/js/mine.js
[pid: 21409|app: 0|req: 3/3] 113.87.160.176 () {38 vars in 672 bytes} [Wed Mar 13 16:38:43 2019] GET /static/mine/js/mine.js => generated 2108 bytes in 4 msecs (HTTP/1.1 404) 3 headers in 102 bytes (1 switches on core 0)
Not Found: /static/mine/js/mine.js
[pid: 21409|app: 0|req: 4/4] 113.87.160.176 () {36 vars in 617 bytes} [Wed Mar 13 16:38:43 2019] GET /static/mine/js/mine.js => generated 2108 bytes in 3 msecs (HTTP/1.1 404) 3 headers in 102 bytes (1 switches on core 0)
[pid: 21409|app: 0|req: 5/5] 113.88.14.120 () {38 vars in 707 bytes} [Wed Mar 13 16:38:45 2019] GET /axf/cart/ => generated 2473 bytes in 4 msecs (HTTP/1.1 200) 3 headers in 110 bytes (1 switches on core 0)
Not Found: /static/cart/js/cart.js
[pid: 21409|app: 0|req: 6/6] 113.87.160.176 () {38 vars in 672 bytes} [Wed Mar 13 16:38:45 2019] GET /static/cart/js/cart.js => generated 2108 bytes in 3 msecs (HTTP/1.1 404) 3 headers in 102 bytes (1 switches on core 0)
*** Starting uWSGI 2.0.18 (64bit) on [Wed Mar 13 16:43:40 2019] ***
compiled with version: 5.4.0 20160609 on 13 March 2019 08:00:41
os: Linux-4.4.0-142-generic #168-Ubuntu SMP Wed Jan 16 21:00:45 UTC 2019
nodename: iZwz98nqijeqfo9ffbtx0zZ
machine: x86_64
clock source: unix
detected number of CPU cores: 1
current working directory: /var/www/axf
writing pidfile to uwsgi.pid
detected binary path: /root/.virtualenvs/python3/bin/uwsgi
!!! no internal routing support, rebuild with pcre support !!!
uWSGI running as root, you can use --uid/--gid/--chroot options
*** WARNING: you are running uWSGI as root !!! (use the --uid flag) *** 
chdir() to /var/www/axf
*** WARNING: you are running uWSGI without its master process manager ***
your processes number limit is 3817
your memory page size is 4096 bytes
detected max file descriptor number: 65535
lock engine: pthread robust mutexes
thunder lock: disabled (you can enable it with --thunder-lock)
uWSGI http bound on 0.0.0.0:8020 fd 4
spawned uWSGI http 1 (pid: 21429)
uwsgi socket 0 bound to TCP address 127.0.0.1:36683 (port auto-assigned) fd 3
uWSGI running as root, you can use --uid/--gid/--chroot options
*** WARNING: you are running uWSGI as root !!! (use the --uid flag) *** 
Python version: 3.5.2 (default, Nov 12 2018, 13:43:14)  [GCC 5.4.0 20160609]
*** Python threads support is disabled. You can enable it with --enable-threads ***
Python main interpreter initialized at 0x1c725a0
uWSGI running as root, you can use --uid/--gid/--chroot options
*** WARNING: you are running uWSGI as root !!! (use the --uid flag) *** 
your server socket listen backlog is limited to 100 connections
your mercy for graceful operations on workers is 60 seconds
mapped 72904 bytes (71 KB) for 1 cores
*** Operational MODE: single process ***
WSGI app 0 (mountpoint='') ready in 0 seconds on interpreter 0x1c725a0 pid: 21428 (default app)
uWSGI running as root, you can use --uid/--gid/--chroot options
*** WARNING: you are running uWSGI as root !!! (use the --uid flag) *** 
*** uWSGI is running in multiple interpreter mode ***
spawned uWSGI worker 1 (and the only) (pid: 21428, cores: 1)
[pid: 21428|app: 0|req: 1/1] 113.88.14.120 () {36 vars in 655 bytes} [Wed Mar 13 16:43:58 2019] GET /axf/cart/ => generated 2473 bytes in 23 msecs (HTTP/1.1 200) 3 headers in 110 bytes (1 switches on core 0)
Not Found: /static/base/css/reset.css
[pid: 21428|app: 0|req: 2/2] 113.87.160.176 () {36 vars in 638 bytes} [Wed Mar 13 16:43:58 2019] GET /static/base/css/reset.css => generated 2117 bytes in 4 msecs (HTTP/1.1 404) 3 headers in 102 bytes (1 switches on core 0)
Not Found: /static/base/js/jquery.js
[pid: 21428|app: 0|req: 3/3] 113.88.14.120 () {36 vars in 620 bytes} [Wed Mar 13 16:43:58 2019] GET /static/base/js/jquery.js => generated 2114 bytes in 4 msecs (HTTP/1.1 404) 3 headers in 102 bytes (1 switches on core 0)
Not Found: /static/base/js/base.js
[pid: 21428|app: 0|req: 4/4] 113.87.160.176 () {36 vars in 617 bytes} [Wed Mar 13 16:43:58 2019] GET /static/base/js/base.js => generated 2108 bytes in 2 msecs (HTTP/1.1 404) 3 headers in 102 bytes (1 switches on core 0)
Not Found: /static/base/css/base.css
[pid: 21428|app: 0|req: 5/5] 113.87.160.176 () {36 vars in 636 bytes} [Wed Mar 13 16:43:58 2019] GET /static/base/css/base.css => generated 2114 bytes in 2 msecs (HTTP/1.1 404) 3 headers in 102 bytes (1 switches on core 0)
Not Found: /static/cart/css/cart.css
[pid: 21428|app: 0|req: 6/6] 113.88.14.120 () {36 vars in 635 bytes} [Wed Mar 13 16:43:58 2019] GET /static/cart/css/cart.css => generated 2114 bytes in 2 msecs (HTTP/1.1 404) 3 headers in 102 bytes (1 switches on core 0)
Not Found: /static/cart/js/cart.js
[pid: 21428|app: 0|req: 7/7] 113.88.14.120 () {36 vars in 616 bytes} [Wed Mar 13 16:43:58 2019] GET /static/cart/js/cart.js => generated 2108 bytes in 2 msecs (HTTP/1.1 404) 3 headers in 102 bytes (1 switches on core 0)
Not Found: /static/base/js/base.js
[pid: 21428|app: 0|req: 8/8] 113.88.14.120 () {36 vars in 616 bytes} [Wed Mar 13 16:43:58 2019] GET /static/base/js/base.js => generated 2108 bytes in 24 msecs (HTTP/1.1 404) 3 headers in 102 bytes (1 switches on core 0)
Not Found: /static/cart/js/cart.js
[pid: 21428|app: 0|req: 9/9] 113.88.14.120 () {36 vars in 616 bytes} [Wed Mar 13 16:43:58 2019] GET /static/cart/js/cart.js => generated 2108 bytes in 4 msecs (HTTP/1.1 404) 3 headers in 102 bytes (1 switches on core 0)
Not Found: /favicon.ico
[pid: 21428|app: 0|req: 10/10] 113.88.14.120 () {36 vars in 630 bytes} [Wed Mar 13 16:43:58 2019] GET /favicon.ico => generated 2075 bytes in 3 msecs (HTTP/1.1 404) 3 headers in 102 bytes (1 switches on core 0)
[pid: 21428|app: 0|req: 11/11] 113.87.160.176 () {38 vars in 687 bytes} [Wed Mar 13 16:44:02 2019] GET /axf/cart/ => generated 2473 bytes in 4 msecs (HTTP/1.1 200) 3 headers in 110 bytes (1 switches on core 0)
Not Found: /static/base/css/reset.css
[pid: 21428|app: 0|req: 12/12] 113.88.14.120 () {36 vars in 637 bytes} [Wed Mar 13 16:44:02 2019] GET /static/base/css/reset.css => generated 2117 bytes in 3 msecs (HTTP/1.1 404) 3 headers in 102 bytes (1 switches on core 0)
Not Found: /static/base/css/base.css
[pid: 21428|app: 0|req: 13/13] 113.88.14.120 () {36 vars in 635 bytes} [Wed Mar 13 16:44:02 2019] GET /static/base/css/base.css => generated 2114 bytes in 2 msecs (HTTP/1.1 404) 3 headers in 102 bytes (1 switches on core 0)
Not Found: /static/cart/css/cart.css
[pid: 21428|app: 0|req: 14/14] 113.88.14.120 () {36 vars in 635 bytes} [Wed Mar 13 16:44:02 2019] GET /static/cart/css/cart.css => generated 2114 bytes in 2 msecs (HTTP/1.1 404) 3 headers in 102 bytes (1 switches on core 0)
Not Found: /static/base/js/jquery.js
[pid: 21428|app: 0|req: 15/15] 113.87.160.176 () {36 vars in 621 bytes} [Wed Mar 13 16:44:02 2019] GET /static/base/js/jquery.js => generated 2114 bytes in 2 msecs (HTTP/1.1 404) 3 headers in 102 bytes (1 switches on core 0)
Not Found: /static/base/js/base.js
[pid: 21428|app: 0|req: 16/16] 113.88.14.120 () {36 vars in 616 bytes} [Wed Mar 13 16:44:02 2019] GET /static/base/js/base.js => generated 2108 bytes in 2 msecs (HTTP/1.1 404) 3 headers in 102 bytes (1 switches on core 0)
Not Found: /static/cart/js/cart.js
[pid: 21428|app: 0|req: 17/17] 113.87.160.176 () {36 vars in 617 bytes} [Wed Mar 13 16:44:02 2019] GET /static/cart/js/cart.js => generated 2108 bytes in 2 msecs (HTTP/1.1 404) 3 headers in 102 bytes (1 switches on core 0)
[pid: 21428|app: 0|req: 18/18] 113.87.160.176 () {38 vars in 698 bytes} [Wed Mar 13 16:44:04 2019] GET /axf/ => generated 21767 bytes in 22 msecs (HTTP/1.1 200) 3 headers in 111 bytes (1 switches on core 0)
Not Found: /static/base/css/reset.css
[pid: 21428|app: 0|req: 19/19] 113.88.14.120 () {36 vars in 632 bytes} [Wed Mar 13 16:44:04 2019] GET /static/base/css/reset.css => generated 2117 bytes in 3 msecs (HTTP/1.1 404) 3 headers in 102 bytes (1 switches on core 0)
Not Found: /static/base/css/base.css
[pid: 21428|app: 0|req: 20/20] 113.87.160.176 () {36 vars in 631 bytes} [Wed Mar 13 16:44:04 2019] GET /static/base/css/base.css => generated 2114 bytes in 3 msecs (HTTP/1.1 404) 3 headers in 102 bytes (1 switches on core 0)
Not Found: /static/home/css/home.css
[pid: 21428|app: 0|req: 21/21] 113.88.14.120 () {36 vars in 630 bytes} [Wed Mar 13 16:44:04 2019] GET /static/home/css/home.css => generated 2114 bytes in 2 msecs (HTTP/1.1 404) 3 headers in 102 bytes (1 switches on core 0)
Not Found: /static/home/css/swiper.min.css
[pid: 21428|app: 0|req: 22/22] 113.88.14.120 () {36 vars in 642 bytes} [Wed Mar 13 16:44:04 2019] GET /static/home/css/swiper.min.css => generated 2132 bytes in 2 msecs (HTTP/1.1 404) 3 headers in 102 bytes (1 switches on core 0)
Not Found: /static/base/js/jquery.js
[pid: 21428|app: 0|req: 23/23] 113.87.160.176 () {36 vars in 616 bytes} [Wed Mar 13 16:44:04 2019] GET /static/base/js/jquery.js => generated 2114 bytes in 2 msecs (HTTP/1.1 404) 3 headers in 102 bytes (1 switches on core 0)
Not Found: /static/base/js/base.js
[pid: 21428|app: 0|req: 24/24] 113.88.14.120 () {36 vars in 611 bytes} [Wed Mar 13 16:44:04 2019] GET /static/base/js/base.js => generated 2108 bytes in 2 msecs (HTTP/1.1 404) 3 headers in 102 bytes (1 switches on core 0)
Not Found: /static/home/js/swiper.min.js
[pid: 21428|app: 0|req: 25/25] 113.87.160.176 () {36 vars in 624 bytes} [Wed Mar 13 16:44:04 2019] GET /static/home/js/swiper.min.js => generated 2126 bytes in 5 msecs (HTTP/1.1 404) 3 headers in 102 bytes (1 switches on core 0)
Not Found: /static/home/js/home.js
[pid: 21428|app: 0|req: 26/26] 113.88.14.120 () {36 vars in 611 bytes} [Wed Mar 13 16:44:04 2019] GET /static/home/js/home.js => generated 2108 bytes in 2 msecs (HTTP/1.1 404) 3 headers in 102 bytes (1 switches on core 0)
*** Starting uWSGI 2.0.18 (64bit) on [Wed Mar 13 17:16:27 2019] ***
compiled with version: 5.4.0 20160609 on 13 March 2019 08:00:41
os: Linux-4.4.0-142-generic #168-Ubuntu SMP Wed Jan 16 21:00:45 UTC 2019
nodename: iZwz98nqijeqfo9ffbtx0zZ
machine: x86_64
clock source: unix
detected number of CPU cores: 1
current working directory: /var/www/axf
writing pidfile to uwsgi.pid
detected binary path: /root/.virtualenvs/python3/bin/uwsgi
!!! no internal routing support, rebuild with pcre support !!!
uWSGI running as root, you can use --uid/--gid/--chroot options
*** WARNING: you are running uWSGI as root !!! (use the --uid flag) *** 
chdir() to /var/www/axf
*** WARNING: you are running uWSGI without its master process manager ***
your processes number limit is 3817
your memory page size is 4096 bytes
detected max file descriptor number: 65535
lock engine: pthread robust mutexes
thunder lock: disabled (you can enable it with --thunder-lock)
uWSGI running as root, you can use --uid/--gid/--chroot options
*** WARNING: you are running uWSGI as root !!! (use the --uid flag) *** 
uWSGI running as root, you can use --uid/--gid/--chroot options
*** WARNING: you are running uWSGI as root !!! (use the --uid flag) *** 
The -s/--socket option is missing and stdin is not a socket.
*** Starting uWSGI 2.0.18 (64bit) on [Wed Mar 13 17:21:58 2019] ***
compiled with version: 5.4.0 20160609 on 13 March 2019 08:00:41
os: Linux-4.4.0-142-generic #168-Ubuntu SMP Wed Jan 16 21:00:45 UTC 2019
nodename: iZwz98nqijeqfo9ffbtx0zZ
machine: x86_64
clock source: unix
detected number of CPU cores: 1
current working directory: /var/www/axf
writing pidfile to uwsgi.pid
detected binary path: /root/.virtualenvs/python3/bin/uwsgi
!!! no internal routing support, rebuild with pcre support !!!
uWSGI running as root, you can use --uid/--gid/--chroot options
*** WARNING: you are running uWSGI as root !!! (use the --uid flag) *** 
chdir() to /var/www/axf
*** WARNING: you are running uWSGI without its master process manager ***
your processes number limit is 3817
your memory page size is 4096 bytes
detected max file descriptor number: 65535
lock engine: pthread robust mutexes
thunder lock: disabled (you can enable it with --thunder-lock)
uwsgi socket 0 bound to TCP address 0.0.0.0:8030 fd 3
uWSGI running as root, you can use --uid/--gid/--chroot options
*** WARNING: you are running uWSGI as root !!! (use the --uid flag) *** 
Python version: 3.5.2 (default, Nov 12 2018, 13:43:14)  [GCC 5.4.0 20160609]
*** Python threads support is disabled. You can enable it with --enable-threads ***
Python main interpreter initialized at 0x12494b0
uWSGI running as root, you can use --uid/--gid/--chroot options
*** WARNING: you are running uWSGI as root !!! (use the --uid flag) *** 
your server socket listen backlog is limited to 100 connections
your mercy for graceful operations on workers is 60 seconds
mapped 72904 bytes (71 KB) for 1 cores
*** Operational MODE: single process ***
WSGI app 0 (mountpoint='') ready in 1 seconds on interpreter 0x12494b0 pid: 21598 (default app)
uWSGI running as root, you can use --uid/--gid/--chroot options
*** WARNING: you are running uWSGI as root !!! (use the --uid flag) *** 
*** uWSGI is running in multiple interpreter mode ***
spawned uWSGI worker 1 (and the only) (pid: 21598, cores: 1)
Not Found: /
[pid: 21598|app: 0|req: 1/1] 113.88.14.120 () {46 vars in 782 bytes} [Wed Mar 13 17:22:06 2019] GET / => generated 2019 bytes in 8 msecs (HTTP/1.1 404) 3 headers in 102 bytes (1 switches on core 0)
[pid: 21598|app: 0|req: 2/2] 113.88.14.120 () {40 vars in 666 bytes} [Wed Mar 13 17:22:13 2019] GET /axf => generated 0 bytes in 1 msecs (HTTP/1.1 301) 3 headers in 110 bytes (1 switches on core 0)
[pid: 21598|app: 0|req: 3/3] 113.88.14.120 () {40 vars in 668 bytes} [Wed Mar 13 17:22:13 2019] GET /axf/ => generated 21767 bytes in 55 msecs (HTTP/1.1 200) 3 headers in 111 bytes (1 switches on core 0)
[pid: 21598|app: 0|req: 4/4] 113.87.160.176 () {42 vars in 725 bytes} [Wed Mar 13 17:22:48 2019] GET /axf/market/ => generated 11067 bytes in 17 msecs (HTTP/1.1 200) 3 headers in 111 bytes (1 switches on core 0)
[pid: 21598|app: 0|req: 5/5] 113.87.160.176 () {42 vars in 679 bytes} [Wed Mar 13 17:22:49 2019] GET /axf/addcart/?goodsid=495 => generated 61 bytes in 1 msecs (HTTP/1.1 200) 4 headers in 114 bytes (1 switches on core 0)
[pid: 21598|app: 0|req: 6/6] 113.87.160.176 () {44 vars in 756 bytes} [Wed Mar 13 17:22:49 2019] GET /axf/login/ => generated 2138 bytes in 4 msecs (HTTP/1.1 200) 5 headers in 278 bytes (1 switches on core 0)
123123@qq.com 123123
[pid: 21598|app: 0|req: 7/7] 113.87.160.176 () {52 vars in 1015 bytes} [Wed Mar 13 17:23:01 2019] POST /axf/login/ => generated 0 bytes in 23 msecs (HTTP/1.1 302) 6 headers in 279 bytes (1 switches on core 0)
[pid: 21598|app: 0|req: 8/8] 113.87.160.176 () {46 vars in 908 bytes} [Wed Mar 13 17:23:01 2019] GET /axf/market/ => generated 11067 bytes in 13 msecs (HTTP/1.1 200) 3 headers in 111 bytes (1 switches on core 0)
[pid: 21598|app: 0|req: 9/9] 113.87.160.176 () {42 vars in 815 bytes} [Wed Mar 13 17:27:43 2019] GET /axf/ => generated 21767 bytes in 19 msecs (HTTP/1.1 200) 3 headers in 111 bytes (1 switches on core 0)
Not Found: /favicon.ico
[pid: 21598|app: 0|req: 10/10] 113.87.160.176 () {42 vars in 790 bytes} [Wed Mar 13 17:27:43 2019] GET /favicon.ico => generated 2070 bytes in 3 msecs (HTTP/1.1 404) 3 headers in 102 bytes (1 switches on core 0)
Not Found: /
[pid: 21598|app: 0|req: 11/11] 138.118.102.6 () {32 vars in 452 bytes} [Wed Mar 13 18:18:31 2019] GET / => generated 2022 bytes in 3 msecs (HTTP/1.1 404) 3 headers in 102 bytes (1 switches on core 0)
Not Found: /
[pid: 21598|app: 0|req: 12/12] 47.101.204.94 () {34 vars in 461 bytes} [Wed Mar 13 18:44:28 2019] GET / => generated 2019 bytes in 3 msecs (HTTP/1.1 404) 3 headers in 102 bytes (1 switches on core 0)
Not Found: /
[pid: 21598|app: 0|req: 13/13] 202.142.135.6 () {32 vars in 452 bytes} [Wed Mar 13 18:53:45 2019] GET / => generated 2022 bytes in 4 msecs (HTTP/1.1 404) 3 headers in 102 bytes (1 switches on core 0)
Invalid HTTP_HOST header: ''. The domain name provided is not valid according to RFC 1034/1035.
[pid: 21598|app: 0|req: 14/14] 216.245.197.254 () {26 vars in 285 bytes} [Wed Mar 13 19:12:59 2019] HEAD /robots.txt => generated 55318 bytes in 47 msecs (HTTP/1.0 400) 1 headers in 53 bytes (1 switches on core 0)
Not Found: /
[pid: 21598|app: 0|req: 15/15] 194.44.161.162 () {32 vars in 453 bytes} [Wed Mar 13 19:18:04 2019] GET / => generated 2022 bytes in 3 msecs (HTTP/1.1 404) 3 headers in 102 bytes (1 switches on core 0)
Not Found: /
[pid: 21598|app: 0|req: 16/16] 139.162.119.197 () {32 vars in 383 bytes} [Wed Mar 13 20:06:19 2019] GET / => generated 2019 bytes in 3 msecs (HTTP/1.1 404) 3 headers in 102 bytes (1 switches on core 0)
Not Found: /echo.php
[pid: 21598|app: 0|req: 17/17] 139.162.88.63 () {32 vars in 401 bytes} [Wed Mar 13 20:14:39 2019] GET /echo.php?info=1234567890 => generated 2081 bytes in 3 msecs (HTTP/1.1 404) 3 headers in 102 bytes (1 switches on core 0)
Not Found: /
[pid: 21598|app: 0|req: 18/18] 47.101.204.90 () {34 vars in 461 bytes} [Wed Mar 13 20:25:05 2019] GET / => generated 2019 bytes in 3 msecs (HTTP/1.1 404) 3 headers in 102 bytes (1 switches on core 0)
Not Found: /
[pid: 21598|app: 0|req: 19/19] 212.129.50.159 () {30 vars in 319 bytes} [Wed Mar 13 20:44:03 2019] GET / => generated 2019 bytes in 3 msecs (HTTP/1.1 404) 3 headers in 102 bytes (1 switches on core 0)
*** Starting uWSGI 2.0.18 (64bit) on [Wed Mar 13 21:12:07 2019] ***
compiled with version: 5.4.0 20160609 on 13 March 2019 08:00:41
os: Linux-4.4.0-142-generic #168-Ubuntu SMP Wed Jan 16 21:00:45 UTC 2019
nodename: iZwz98nqijeqfo9ffbtx0zZ
machine: x86_64
clock source: unix
detected number of CPU cores: 1
current working directory: /var/www/axf
writing pidfile to uwsgi.pid
detected binary path: /root/.virtualenvs/python3/bin/uwsgi
!!! no internal routing support, rebuild with pcre support !!!
uWSGI running as root, you can use --uid/--gid/--chroot options
*** WARNING: you are running uWSGI as root !!! (use the --uid flag) *** 
chdir() to /var/www/axf
*** WARNING: you are running uWSGI without its master process manager ***
your processes number limit is 3817
your memory page size is 4096 bytes
detected max file descriptor number: 65535
lock engine: pthread robust mutexes
thunder lock: disabled (you can enable it with --thunder-lock)
uwsgi socket 0 bound to TCP address 0.0.0.0:8030 fd 3
uWSGI running as root, you can use --uid/--gid/--chroot options
*** WARNING: you are running uWSGI as root !!! (use the --uid flag) *** 
Python version: 3.5.2 (default, Nov 12 2018, 13:43:14)  [GCC 5.4.0 20160609]
*** Python threads support is disabled. You can enable it with --enable-threads ***
Python main interpreter initialized at 0x176d4b0
uWSGI running as root, you can use --uid/--gid/--chroot options
*** WARNING: you are running uWSGI as root !!! (use the --uid flag) *** 
your server socket listen backlog is limited to 100 connections
your mercy for graceful operations on workers is 60 seconds
mapped 72904 bytes (71 KB) for 1 cores
*** Operational MODE: single process ***
WSGI app 0 (mountpoint='') ready in 1 seconds on interpreter 0x176d4b0 pid: 21815 (default app)
uWSGI running as root, you can use --uid/--gid/--chroot options
*** WARNING: you are running uWSGI as root !!! (use the --uid flag) *** 
*** uWSGI is running in multiple interpreter mode ***
spawned uWSGI worker 1 (and the only) (pid: 21815, cores: 1)
[pid: 21815|app: 0|req: 1/1] 113.88.14.120 () {42 vars in 814 bytes} [Wed Mar 13 21:12:33 2019] GET /axf/ => generated 21767 bytes in 68 msecs (HTTP/1.1 200) 3 headers in 111 bytes (1 switches on core 0)
Not Found: /favicon.ico
[pid: 21815|app: 0|req: 2/2] 113.88.14.120 () {42 vars in 789 bytes} [Wed Mar 13 21:12:34 2019] GET /favicon.ico => generated 2070 bytes in 3 msecs (HTTP/1.1 404) 3 headers in 102 bytes (1 switches on core 0)
Internal Server Error: /axf/mine/
Traceback (most recent call last):
  File "/root/.virtualenvs/python3/lib/python3.5/site-packages/django/db/backends/utils.py", line 65, in execute
    return self.cursor.execute(sql, params)
  File "/root/.virtualenvs/python3/lib/python3.5/site-packages/django/db/backends/mysql/base.py", line 101, in execute
    return self.cursor.execute(query, args)
  File "/root/.virtualenvs/python3/lib/python3.5/site-packages/pymysql/cursors.py", line 170, in execute
    result = self._query(query)
  File "/root/.virtualenvs/python3/lib/python3.5/site-packages/pymysql/cursors.py", line 328, in _query
    conn.query(q)
  File "/root/.virtualenvs/python3/lib/python3.5/site-packages/pymysql/connections.py", line 517, in query
    self._affected_rows = self._read_query_result(unbuffered=unbuffered)
  File "/root/.virtualenvs/python3/lib/python3.5/site-packages/pymysql/connections.py", line 732, in _read_query_result
    result.read()
  File "/root/.virtualenvs/python3/lib/python3.5/site-packages/pymysql/connections.py", line 1075, in read
    first_packet = self.connection._read_packet()
  File "/root/.virtualenvs/python3/lib/python3.5/site-packages/pymysql/connections.py", line 684, in _read_packet
    packet.check_error()
  File "/root/.virtualenvs/python3/lib/python3.5/site-packages/pymysql/protocol.py", line 220, in check_error
    err.raise_mysql_exception(self._data)
  File "/root/.virtualenvs/python3/lib/python3.5/site-packages/pymysql/err.py", line 109, in raise_mysql_exception
    raise errorclass(errno, errval)
pymysql.err.ProgrammingError: (1146, "Table 'python1812axf.app_order' doesn't exist")

The above exception was the direct cause of the following exception:

Traceback (most recent call last):
  File "/root/.virtualenvs/python3/lib/python3.5/site-packages/django/core/handlers/exception.py", line 41, in inner
    response = get_response(request)
  File "/root/.virtualenvs/python3/lib/python3.5/site-packages/django/core/handlers/base.py", line 187, in _get_response
    response = self.process_exception_by_middleware(e, request)
  File "/root/.virtualenvs/python3/lib/python3.5/site-packages/django/core/handlers/base.py", line 185, in _get_response
    response = wrapped_callback(request, *callback_args, **callback_kwargs)
  File "./app/views.py", line 153, in mine
    response_data['waitpay'] = orders.filter(status=0).count()
  File "/root/.virtualenvs/python3/lib/python3.5/site-packages/django/db/models/query.py", line 364, in count
    return self.query.get_count(using=self.db)
  File "/root/.virtualenvs/python3/lib/python3.5/site-packages/django/db/models/sql/query.py", line 499, in get_count
    number = obj.get_aggregation(using, ['__count'])['__count']
  File "/root/.virtualenvs/python3/lib/python3.5/site-packages/django/db/models/sql/query.py", line 480, in get_aggregation
    result = compiler.execute_sql(SINGLE)
  File "/root/.virtualenvs/python3/lib/python3.5/site-packages/django/db/models/sql/compiler.py", line 894, in execute_sql
    raise original_exception
  File "/root/.virtualenvs/python3/lib/python3.5/site-packages/django/db/models/sql/compiler.py", line 884, in execute_sql
    cursor.execute(sql, params)
  File "/root/.virtualenvs/python3/lib/python3.5/site-packages/django/db/backends/utils.py", line 80, in execute
    return super(CursorDebugWrapper, self).execute(sql, params)
  File "/root/.virtualenvs/python3/lib/python3.5/site-packages/django/db/backends/utils.py", line 65, in execute
    return self.cursor.execute(sql, params)
  File "/root/.virtualenvs/python3/lib/python3.5/site-packages/django/db/utils.py", line 94, in __exit__
    six.reraise(dj_exc_type, dj_exc_value, traceback)
  File "/root/.virtualenvs/python3/lib/python3.5/site-packages/django/utils/six.py", line 685, in reraise
    raise value.with_traceback(tb)
  File "/root/.virtualenvs/python3/lib/python3.5/site-packages/django/db/backends/utils.py", line 65, in execute
    return self.cursor.execute(sql, params)
  File "/root/.virtualenvs/python3/lib/python3.5/site-packages/django/db/backends/mysql/base.py", line 101, in execute
    return self.cursor.execute(query, args)
  File "/root/.virtualenvs/python3/lib/python3.5/site-packages/pymysql/cursors.py", line 170, in execute
    result = self._query(query)
  File "/root/.virtualenvs/python3/lib/python3.5/site-packages/pymysql/cursors.py", line 328, in _query
    conn.query(q)
  File "/root/.virtualenvs/python3/lib/python3.5/site-packages/pymysql/connections.py", line 517, in query
    self._affected_rows = self._read_query_result(unbuffered=unbuffered)
  File "/root/.virtualenvs/python3/lib/python3.5/site-packages/pymysql/connections.py", line 732, in _read_query_result
    result.read()
  File "/root/.virtualenvs/python3/lib/python3.5/site-packages/pymysql/connections.py", line 1075, in read
    first_packet = self.connection._read_packet()
  File "/root/.virtualenvs/python3/lib/python3.5/site-packages/pymysql/connections.py", line 684, in _read_packet
    packet.check_error()
  File "/root/.virtualenvs/python3/lib/python3.5/site-packages/pymysql/protocol.py", line 220, in check_error
    err.raise_mysql_exception(self._data)
  File "/root/.virtualenvs/python3/lib/python3.5/site-packages/pymysql/err.py", line 109, in raise_mysql_exception
    raise errorclass(errno, errval)
django.db.utils.ProgrammingError: (1146, "Table 'python1812axf.app_order' doesn't exist")
[pid: 21815|app: 0|req: 3/3] 113.88.14.120 () {44 vars in 866 bytes} [Wed Mar 13 21:12:58 2019] GET /axf/mine/ => generated 183322 bytes in 146 msecs (HTTP/1.1 500) 4 headers in 130 bytes (1 switches on core 0)
[pid: 21815|app: 0|req: 4/4] 113.88.14.120 () {42 vars in 814 bytes} [Wed Mar 13 21:13:08 2019] GET /axf/ => generated 21767 bytes in 18 msecs (HTTP/1.1 200) 3 headers in 111 bytes (1 switches on core 0)
[pid: 21815|app: 0|req: 5/5] 113.88.14.120 () {44 vars in 845 bytes} [Wed Mar 13 21:13:25 2019] GET /axf/ => generated 21767 bytes in 17 msecs (HTTP/1.1 200) 3 headers in 111 bytes (1 switches on core 0)
Internal Server Error: /axf/mine/
Traceback (most recent call last):
  File "/root/.virtualenvs/python3/lib/python3.5/site-packages/django/db/backends/utils.py", line 65, in execute
    return self.cursor.execute(sql, params)
  File "/root/.virtualenvs/python3/lib/python3.5/site-packages/django/db/backends/mysql/base.py", line 101, in execute
    return self.cursor.execute(query, args)
  File "/root/.virtualenvs/python3/lib/python3.5/site-packages/pymysql/cursors.py", line 170, in execute
    result = self._query(query)
  File "/root/.virtualenvs/python3/lib/python3.5/site-packages/pymysql/cursors.py", line 328, in _query
    conn.query(q)
  File "/root/.virtualenvs/python3/lib/python3.5/site-packages/pymysql/connections.py", line 517, in query
    self._affected_rows = self._read_query_result(unbuffered=unbuffered)
  File "/root/.virtualenvs/python3/lib/python3.5/site-packages/pymysql/connections.py", line 732, in _read_query_result
    result.read()
  File "/root/.virtualenvs/python3/lib/python3.5/site-packages/pymysql/connections.py", line 1075, in read
    first_packet = self.connection._read_packet()
  File "/root/.virtualenvs/python3/lib/python3.5/site-packages/pymysql/connections.py", line 684, in _read_packet
    packet.check_error()
  File "/root/.virtualenvs/python3/lib/python3.5/site-packages/pymysql/protocol.py", line 220, in check_error
    err.raise_mysql_exception(self._data)
  File "/root/.virtualenvs/python3/lib/python3.5/site-packages/pymysql/err.py", line 109, in raise_mysql_exception
    raise errorclass(errno, errval)
pymysql.err.ProgrammingError: (1146, "Table 'python1812axf.app_order' doesn't exist")

The above exception was the direct cause of the following exception:

Traceback (most recent call last):
  File "/root/.virtualenvs/python3/lib/python3.5/site-packages/django/core/handlers/exception.py", line 41, in inner
    response = get_response(request)
  File "/root/.virtualenvs/python3/lib/python3.5/site-packages/django/core/handlers/base.py", line 187, in _get_response
    response = self.process_exception_by_middleware(e, request)
  File "/root/.virtualenvs/python3/lib/python3.5/site-packages/django/core/handlers/base.py", line 185, in _get_response
    response = wrapped_callback(request, *callback_args, **callback_kwargs)
  File "./app/views.py", line 153, in mine
    response_data['waitpay'] = orders.filter(status=0).count()
  File "/root/.virtualenvs/python3/lib/python3.5/site-packages/django/db/models/query.py", line 364, in count
    return self.query.get_count(using=self.db)
  File "/root/.virtualenvs/python3/lib/python3.5/site-packages/django/db/models/sql/query.py", line 499, in get_count
    number = obj.get_aggregation(using, ['__count'])['__count']
  File "/root/.virtualenvs/python3/lib/python3.5/site-packages/django/db/models/sql/query.py", line 480, in get_aggregation
    result = compiler.execute_sql(SINGLE)
  File "/root/.virtualenvs/python3/lib/python3.5/site-packages/django/db/models/sql/compiler.py", line 894, in execute_sql
    raise original_exception
  File "/root/.virtualenvs/python3/lib/python3.5/site-packages/django/db/models/sql/compiler.py", line 884, in execute_sql
    cursor.execute(sql, params)
  File "/root/.virtualenvs/python3/lib/python3.5/site-packages/django/db/backends/utils.py", line 80, in execute
    return super(CursorDebugWrapper, self).execute(sql, params)
  File "/root/.virtualenvs/python3/lib/python3.5/site-packages/django/db/backends/utils.py", line 65, in execute
    return self.cursor.execute(sql, params)
  File "/root/.virtualenvs/python3/lib/python3.5/site-packages/django/db/utils.py", line 94, in __exit__
    six.reraise(dj_exc_type, dj_exc_value, traceback)
  File "/root/.virtualenvs/python3/lib/python3.5/site-packages/django/utils/six.py", line 685, in reraise
    raise value.with_traceback(tb)
  File "/root/.virtualenvs/python3/lib/python3.5/site-packages/django/db/backends/utils.py", line 65, in execute
    return self.cursor.execute(sql, params)
  File "/root/.virtualenvs/python3/lib/python3.5/site-packages/django/db/backends/mysql/base.py", line 101, in execute
    return self.cursor.execute(query, args)
  File "/root/.virtualenvs/python3/lib/python3.5/site-packages/pymysql/cursors.py", line 170, in execute
    result = self._query(query)
  File "/root/.virtualenvs/python3/lib/python3.5/site-packages/pymysql/cursors.py", line 328, in _query
    conn.query(q)
  File "/root/.virtualenvs/python3/lib/python3.5/site-packages/pymysql/connections.py", line 517, in query
    self._affected_rows = self._read_query_result(unbuffered=unbuffered)
  File "/root/.virtualenvs/python3/lib/python3.5/site-packages/pymysql/connections.py", line 732, in _read_query_result
    result.read()
  File "/root/.virtualenvs/python3/lib/python3.5/site-packages/pymysql/connections.py", line 1075, in read
    first_packet = self.connection._read_packet()
  File "/root/.virtualenvs/python3/lib/python3.5/site-packages/pymysql/connections.py", line 684, in _read_packet
    packet.check_error()
  File "/root/.virtualenvs/python3/lib/python3.5/site-packages/pymysql/protocol.py", line 220, in check_error
    err.raise_mysql_exception(self._data)
  File "/root/.virtualenvs/python3/lib/python3.5/site-packages/pymysql/err.py", line 109, in raise_mysql_exception
    raise errorclass(errno, errval)
django.db.utils.ProgrammingError: (1146, "Table 'python1812axf.app_order' doesn't exist")
[pid: 21815|app: 0|req: 6/6] 113.88.14.120 () {44 vars in 866 bytes} [Wed Mar 13 21:13:27 2019] GET /axf/mine/ => generated 183324 bytes in 85 msecs (HTTP/1.1 500) 4 headers in 130 bytes (1 switches on core 0)
[pid: 21815|app: 0|req: 7/7] 113.88.14.120 () {44 vars in 855 bytes} [Wed Mar 13 21:22:15 2019] GET /axf/mine/ => generated 6232 bytes in 9 msecs (HTTP/1.1 200) 4 headers in 195 bytes (1 switches on core 0)
[pid: 21815|app: 0|req: 8/8] 113.87.160.176 () {44 vars in 828 bytes} [Wed Mar 13 21:22:19 2019] GET /axf/cart/ => generated 2059 bytes in 3 msecs (HTTP/1.1 200) 4 headers in 124 bytes (1 switches on core 0)
[pid: 21815|app: 0|req: 9/9] 113.87.160.176 () {44 vars in 832 bytes} [Wed Mar 13 21:22:20 2019] GET /axf/market/ => generated 11361 bytes in 16 msecs (HTTP/1.1 200) 4 headers in 125 bytes (1 switches on core 0)
[pid: 21815|app: 0|req: 10/10] 113.87.160.176 () {44 vars in 781 bytes} [Wed Mar 13 21:22:22 2019] GET /axf/addcart/?goodsid=495 => generated 61 bytes in 1 msecs (HTTP/1.1 200) 4 headers in 114 bytes (1 switches on core 0)
[pid: 21815|app: 0|req: 11/11] 113.87.160.176 () {44 vars in 832 bytes} [Wed Mar 13 21:22:22 2019] GET /axf/login/ => generated 2138 bytes in 4 msecs (HTTP/1.1 200) 5 headers in 278 bytes (1 switches on core 0)
123123@qq.com 123123
[pid: 21815|app: 0|req: 12/12] 113.87.160.176 () {52 vars in 1015 bytes} [Wed Mar 13 21:22:28 2019] POST /axf/login/ => generated 0 bytes in 13 msecs (HTTP/1.1 302) 6 headers in 279 bytes (1 switches on core 0)
[pid: 21815|app: 0|req: 13/13] 113.87.160.176 () {46 vars in 908 bytes} [Wed Mar 13 21:22:28 2019] GET /axf/market/ => generated 11698 bytes in 30 msecs (HTTP/1.1 200) 4 headers in 125 bytes (1 switches on core 0)
[pid: 21815|app: 0|req: 14/14] 113.87.160.176 () {44 vars in 825 bytes} [Wed Mar 13 21:22:32 2019] GET /axf/subcart/?goodsid=495 => generated 74 bytes in 12 msecs (HTTP/1.1 200) 4 headers in 114 bytes (1 switches on core 0)
[pid: 21815|app: 0|req: 15/15] 113.87.160.176 () {44 vars in 825 bytes} [Wed Mar 13 21:22:33 2019] GET /axf/subcart/?goodsid=495 => generated 73 bytes in 11 msecs (HTTP/1.1 200) 4 headers in 114 bytes (1 switches on core 0)
[pid: 21815|app: 0|req: 16/16] 113.87.160.176 () {44 vars in 825 bytes} [Wed Mar 13 21:22:34 2019] GET /axf/addcart/?goodsid=495 => generated 119 bytes in 15 msecs (HTTP/1.1 200) 4 headers in 115 bytes (1 switches on core 0)
[pid: 21815|app: 0|req: 17/17] 113.87.160.176 () {44 vars in 825 bytes} [Wed Mar 13 21:22:35 2019] GET /axf/addcart/?goodsid=495 => generated 119 bytes in 15 msecs (HTTP/1.1 200) 4 headers in 115 bytes (1 switches on core 0)
[pid: 21815|app: 0|req: 18/18] 113.87.160.176 () {44 vars in 825 bytes} [Wed Mar 13 21:22:35 2019] GET /axf/addcart/?goodsid=495 => generated 119 bytes in 14 msecs (HTTP/1.1 200) 4 headers in 115 bytes (1 switches on core 0)
[pid: 21815|app: 0|req: 19/19] 113.87.160.176 () {44 vars in 825 bytes} [Wed Mar 13 21:22:36 2019] GET /axf/addcart/?goodsid=496 => generated 155 bytes in 12 msecs (HTTP/1.1 200) 4 headers in 115 bytes (1 switches on core 0)
[pid: 21815|app: 0|req: 20/20] 113.87.160.176 () {44 vars in 825 bytes} [Wed Mar 13 21:22:36 2019] GET /axf/addcart/?goodsid=496 => generated 155 bytes in 14 msecs (HTTP/1.1 200) 4 headers in 115 bytes (1 switches on core 0)
[pid: 21815|app: 0|req: 21/21] 113.87.160.176 () {44 vars in 874 bytes} [Wed Mar 13 21:22:38 2019] GET /axf/cart/ => generated 4445 bytes in 14 msecs (HTTP/1.1 200) 4 headers in 124 bytes (1 switches on core 0)
Internal Server Error: /axf/generateorder/
Traceback (most recent call last):
  File "/root/.virtualenvs/python3/lib/python3.5/site-packages/django/db/backends/utils.py", line 65, in execute
    return self.cursor.execute(sql, params)
  File "/root/.virtualenvs/python3/lib/python3.5/site-packages/django/db/backends/mysql/base.py", line 101, in execute
    return self.cursor.execute(query, args)
  File "/root/.virtualenvs/python3/lib/python3.5/site-packages/pymysql/cursors.py", line 170, in execute
    result = self._query(query)
  File "/root/.virtualenvs/python3/lib/python3.5/site-packages/pymysql/cursors.py", line 328, in _query
    conn.query(q)
  File "/root/.virtualenvs/python3/lib/python3.5/site-packages/pymysql/connections.py", line 517, in query
    self._affected_rows = self._read_query_result(unbuffered=unbuffered)
  File "/root/.virtualenvs/python3/lib/python3.5/site-packages/pymysql/connections.py", line 732, in _read_query_result
    result.read()
  File "/root/.virtualenvs/python3/lib/python3.5/site-packages/pymysql/connections.py", line 1075, in read
    first_packet = self.connection._read_packet()
  File "/root/.virtualenvs/python3/lib/python3.5/site-packages/pymysql/connections.py", line 684, in _read_packet
    packet.check_error()
  File "/root/.virtualenvs/python3/lib/python3.5/site-packages/pymysql/protocol.py", line 220, in check_error
    err.raise_mysql_exception(self._data)
  File "/root/.virtualenvs/python3/lib/python3.5/site-packages/pymysql/err.py", line 109, in raise_mysql_exception
    raise errorclass(errno, errval)
pymysql.err.ProgrammingError: (1146, "Table 'python1812axf.app_order' doesn't exist")

The above exception was the direct cause of the following exception:

Traceback (most recent call last):
  File "/root/.virtualenvs/python3/lib/python3.5/site-packages/django/core/handlers/exception.py", line 41, in inner
    response = get_response(request)
  File "/root/.virtualenvs/python3/lib/python3.5/site-packages/django/core/handlers/base.py", line 187, in _get_response
    response = self.process_exception_by_middleware(e, request)
  File "/root/.virtualenvs/python3/lib/python3.5/site-packages/django/core/handlers/base.py", line 185, in _get_response
    response = wrapped_callback(request, *callback_args, **callback_kwargs)
  File "./app/views.py", line 385, in generateorder
    order.save()
  File "/root/.virtualenvs/python3/lib/python3.5/site-packages/django/db/models/base.py", line 807, in save
    force_update=force_update, update_fields=update_fields)
  File "/root/.virtualenvs/python3/lib/python3.5/site-packages/django/db/models/base.py", line 837, in save_base
    updated = self._save_table(raw, cls, force_insert, force_update, using, update_fields)
  File "/root/.virtualenvs/python3/lib/python3.5/site-packages/django/db/models/base.py", line 923, in _save_table
    result = self._do_insert(cls._base_manager, using, fields, update_pk, raw)
  File "/root/.virtualenvs/python3/lib/python3.5/site-packages/django/db/models/base.py", line 962, in _do_insert
    using=using, raw=raw)
  File "/root/.virtualenvs/python3/lib/python3.5/site-packages/django/db/models/manager.py", line 85, in manager_method
    return getattr(self.get_queryset(), name)(*args, **kwargs)
  File "/root/.virtualenvs/python3/lib/python3.5/site-packages/django/db/models/query.py", line 1076, in _insert
    return query.get_compiler(using=using).execute_sql(return_id)
  File "/root/.virtualenvs/python3/lib/python3.5/site-packages/django/db/models/sql/compiler.py", line 1107, in execute_sql
    cursor.execute(sql, params)
  File "/root/.virtualenvs/python3/lib/python3.5/site-packages/django/db/backends/utils.py", line 80, in execute
    return super(CursorDebugWrapper, self).execute(sql, params)
  File "/root/.virtualenvs/python3/lib/python3.5/site-packages/django/db/backends/utils.py", line 65, in execute
    return self.cursor.execute(sql, params)
  File "/root/.virtualenvs/python3/lib/python3.5/site-packages/django/db/utils.py", line 94, in __exit__
    six.reraise(dj_exc_type, dj_exc_value, traceback)
  File "/root/.virtualenvs/python3/lib/python3.5/site-packages/django/utils/six.py", line 685, in reraise
    raise value.with_traceback(tb)
  File "/root/.virtualenvs/python3/lib/python3.5/site-packages/django/db/backends/utils.py", line 65, in execute
    return self.cursor.execute(sql, params)
  File "/root/.virtualenvs/python3/lib/python3.5/site-packages/django/db/backends/mysql/base.py", line 101, in execute
    return self.cursor.execute(query, args)
  File "/root/.virtualenvs/python3/lib/python3.5/site-packages/pymysql/cursors.py", line 170, in execute
    result = self._query(query)
  File "/root/.virtualenvs/python3/lib/python3.5/site-packages/pymysql/cursors.py", line 328, in _query
    conn.query(q)
  File "/root/.virtualenvs/python3/lib/python3.5/site-packages/pymysql/connections.py", line 517, in query
    self._affected_rows = self._read_query_result(unbuffered=unbuffered)
  File "/root/.virtualenvs/python3/lib/python3.5/site-packages/pymysql/connections.py", line 732, in _read_query_result
    result.read()
  File "/root/.virtualenvs/python3/lib/python3.5/site-packages/pymysql/connections.py", line 1075, in read
    first_packet = self.connection._read_packet()
  File "/root/.virtualenvs/python3/lib/python3.5/site-packages/pymysql/connections.py", line 684, in _read_packet
    packet.check_error()
  File "/root/.virtualenvs/python3/lib/python3.5/site-packages/pymysql/protocol.py", line 220, in check_error
    err.raise_mysql_exception(self._data)
  File "/root/.virtualenvs/python3/lib/python3.5/site-packages/pymysql/err.py", line 109, in raise_mysql_exception
    raise errorclass(errno, errval)
django.db.utils.ProgrammingError: (1146, "Table 'python1812axf.app_order' doesn't exist")
[pid: 21815|app: 0|req: 22/22] 113.87.160.176 () {44 vars in 890 bytes} [Wed Mar 13 21:22:44 2019] GET /axf/generateorder/ => generated 199035 bytes in 95 msecs (HTTP/1.1 500) 4 headers in 130 bytes (1 switches on core 0)
Internal Server Error: /axf/generateorder/
Traceback (most recent call last):
  File "/root/.virtualenvs/python3/lib/python3.5/site-packages/django/db/backends/utils.py", line 65, in execute
    return self.cursor.execute(sql, params)
  File "/root/.virtualenvs/python3/lib/python3.5/site-packages/django/db/backends/mysql/base.py", line 101, in execute
    return self.cursor.execute(query, args)
  File "/root/.virtualenvs/python3/lib/python3.5/site-packages/pymysql/cursors.py", line 170, in execute
    result = self._query(query)
  File "/root/.virtualenvs/python3/lib/python3.5/site-packages/pymysql/cursors.py", line 328, in _query
    conn.query(q)
  File "/root/.virtualenvs/python3/lib/python3.5/site-packages/pymysql/connections.py", line 517, in query
    self._affected_rows = self._read_query_result(unbuffered=unbuffered)
  File "/root/.virtualenvs/python3/lib/python3.5/site-packages/pymysql/connections.py", line 732, in _read_query_result
    result.read()
  File "/root/.virtualenvs/python3/lib/python3.5/site-packages/pymysql/connections.py", line 1075, in read
    first_packet = self.connection._read_packet()
  File "/root/.virtualenvs/python3/lib/python3.5/site-packages/pymysql/connections.py", line 684, in _read_packet
    packet.check_error()
  File "/root/.virtualenvs/python3/lib/python3.5/site-packages/pymysql/protocol.py", line 220, in check_error
    err.raise_mysql_exception(self._data)
  File "/root/.virtualenvs/python3/lib/python3.5/site-packages/pymysql/err.py", line 109, in raise_mysql_exception
    raise errorclass(errno, errval)
pymysql.err.ProgrammingError: (1146, "Table 'python1812axf.app_order' doesn't exist")

The above exception was the direct cause of the following exception:

Traceback (most recent call last):
  File "/root/.virtualenvs/python3/lib/python3.5/site-packages/django/core/handlers/exception.py", line 41, in inner
    response = get_response(request)
  File "/root/.virtualenvs/python3/lib/python3.5/site-packages/django/core/handlers/base.py", line 187, in _get_response
    response = self.process_exception_by_middleware(e, request)
  File "/root/.virtualenvs/python3/lib/python3.5/site-packages/django/core/handlers/base.py", line 185, in _get_response
    response = wrapped_callback(request, *callback_args, **callback_kwargs)
  File "./app/views.py", line 385, in generateorder
    order.save()
  File "/root/.virtualenvs/python3/lib/python3.5/site-packages/django/db/models/base.py", line 807, in save
    force_update=force_update, update_fields=update_fields)
  File "/root/.virtualenvs/python3/lib/python3.5/site-packages/django/db/models/base.py", line 837, in save_base
    updated = self._save_table(raw, cls, force_insert, force_update, using, update_fields)
  File "/root/.virtualenvs/python3/lib/python3.5/site-packages/django/db/models/base.py", line 923, in _save_table
    result = self._do_insert(cls._base_manager, using, fields, update_pk, raw)
  File "/root/.virtualenvs/python3/lib/python3.5/site-packages/django/db/models/base.py", line 962, in _do_insert
    using=using, raw=raw)
  File "/root/.virtualenvs/python3/lib/python3.5/site-packages/django/db/models/manager.py", line 85, in manager_method
    return getattr(self.get_queryset(), name)(*args, **kwargs)
  File "/root/.virtualenvs/python3/lib/python3.5/site-packages/django/db/models/query.py", line 1076, in _insert
    return query.get_compiler(using=using).execute_sql(return_id)
  File "/root/.virtualenvs/python3/lib/python3.5/site-packages/django/db/models/sql/compiler.py", line 1107, in execute_sql
    cursor.execute(sql, params)
  File "/root/.virtualenvs/python3/lib/python3.5/site-packages/django/db/backends/utils.py", line 80, in execute
    return super(CursorDebugWrapper, self).execute(sql, params)
  File "/root/.virtualenvs/python3/lib/python3.5/site-packages/django/db/backends/utils.py", line 65, in execute
    return self.cursor.execute(sql, params)
  File "/root/.virtualenvs/python3/lib/python3.5/site-packages/django/db/utils.py", line 94, in __exit__
    six.reraise(dj_exc_type, dj_exc_value, traceback)
  File "/root/.virtualenvs/python3/lib/python3.5/site-packages/django/utils/six.py", line 685, in reraise
    raise value.with_traceback(tb)
  File "/root/.virtualenvs/python3/lib/python3.5/site-packages/django/db/backends/utils.py", line 65, in execute
    return self.cursor.execute(sql, params)
  File "/root/.virtualenvs/python3/lib/python3.5/site-packages/django/db/backends/mysql/base.py", line 101, in execute
    return self.cursor.execute(query, args)
  File "/root/.virtualenvs/python3/lib/python3.5/site-packages/pymysql/cursors.py", line 170, in execute
    result = self._query(query)
  File "/root/.virtualenvs/python3/lib/python3.5/site-packages/pymysql/cursors.py", line 328, in _query
    conn.query(q)
  File "/root/.virtualenvs/python3/lib/python3.5/site-packages/pymysql/connections.py", line 517, in query
    self._affected_rows = self._read_query_result(unbuffered=unbuffered)
  File "/root/.virtualenvs/python3/lib/python3.5/site-packages/pymysql/connections.py", line 732, in _read_query_result
    result.read()
  File "/root/.virtualenvs/python3/lib/python3.5/site-packages/pymysql/connections.py", line 1075, in read
    first_packet = self.connection._read_packet()
  File "/root/.virtualenvs/python3/lib/python3.5/site-packages/pymysql/connections.py", line 684, in _read_packet
    packet.check_error()
  File "/root/.virtualenvs/python3/lib/python3.5/site-packages/pymysql/protocol.py", line 220, in check_error
    err.raise_mysql_exception(self._data)
  File "/root/.virtualenvs/python3/lib/python3.5/site-packages/pymysql/err.py", line 109, in raise_mysql_exception
    raise errorclass(errno, errval)
django.db.utils.ProgrammingError: (1146, "Table 'python1812axf.app_order' doesn't exist")
[pid: 21815|app: 0|req: 23/23] 113.87.160.176 () {44 vars in 874 bytes} [Wed Mar 13 21:23:29 2019] GET /axf/generateorder/ => generated 198986 bytes in 98 msecs (HTTP/1.1 500) 4 headers in 130 bytes (1 switches on core 0)
Internal Server Error: /axf/generateorder/
Traceback (most recent call last):
  File "/root/.virtualenvs/python3/lib/python3.5/site-packages/django/db/backends/utils.py", line 65, in execute
    return self.cursor.execute(sql, params)
  File "/root/.virtualenvs/python3/lib/python3.5/site-packages/django/db/backends/mysql/base.py", line 101, in execute
    return self.cursor.execute(query, args)
  File "/root/.virtualenvs/python3/lib/python3.5/site-packages/pymysql/cursors.py", line 170, in execute
    result = self._query(query)
  File "/root/.virtualenvs/python3/lib/python3.5/site-packages/pymysql/cursors.py", line 328, in _query
    conn.query(q)
  File "/root/.virtualenvs/python3/lib/python3.5/site-packages/pymysql/connections.py", line 517, in query
    self._affected_rows = self._read_query_result(unbuffered=unbuffered)
  File "/root/.virtualenvs/python3/lib/python3.5/site-packages/pymysql/connections.py", line 732, in _read_query_result
    result.read()
  File "/root/.virtualenvs/python3/lib/python3.5/site-packages/pymysql/connections.py", line 1075, in read
    first_packet = self.connection._read_packet()
  File "/root/.virtualenvs/python3/lib/python3.5/site-packages/pymysql/connections.py", line 684, in _read_packet
    packet.check_error()
  File "/root/.virtualenvs/python3/lib/python3.5/site-packages/pymysql/protocol.py", line 220, in check_error
    err.raise_mysql_exception(self._data)
  File "/root/.virtualenvs/python3/lib/python3.5/site-packages/pymysql/err.py", line 109, in raise_mysql_exception
    raise errorclass(errno, errval)
pymysql.err.ProgrammingError: (1146, "Table 'python1812axf.app_order' doesn't exist")

The above exception was the direct cause of the following exception:

Traceback (most recent call last):
  File "/root/.virtualenvs/python3/lib/python3.5/site-packages/django/core/handlers/exception.py", line 41, in inner
    response = get_response(request)
  File "/root/.virtualenvs/python3/lib/python3.5/site-packages/django/core/handlers/base.py", line 187, in _get_response
    response = self.process_exception_by_middleware(e, request)
  File "/root/.virtualenvs/python3/lib/python3.5/site-packages/django/core/handlers/base.py", line 185, in _get_response
    response = wrapped_callback(request, *callback_args, **callback_kwargs)
  File "./app/views.py", line 385, in generateorder
    order.save()
  File "/root/.virtualenvs/python3/lib/python3.5/site-packages/django/db/models/base.py", line 807, in save
    force_update=force_update, update_fields=update_fields)
  File "/root/.virtualenvs/python3/lib/python3.5/site-packages/django/db/models/base.py", line 837, in save_base
    updated = self._save_table(raw, cls, force_insert, force_update, using, update_fields)
  File "/root/.virtualenvs/python3/lib/python3.5/site-packages/django/db/models/base.py", line 923, in _save_table
    result = self._do_insert(cls._base_manager, using, fields, update_pk, raw)
  File "/root/.virtualenvs/python3/lib/python3.5/site-packages/django/db/models/base.py", line 962, in _do_insert
    using=using, raw=raw)
  File "/root/.virtualenvs/python3/lib/python3.5/site-packages/django/db/models/manager.py", line 85, in manager_method
    return getattr(self.get_queryset(), name)(*args, **kwargs)
  File "/root/.virtualenvs/python3/lib/python3.5/site-packages/django/db/models/query.py", line 1076, in _insert
    return query.get_compiler(using=using).execute_sql(return_id)
  File "/root/.virtualenvs/python3/lib/python3.5/site-packages/django/db/models/sql/compiler.py", line 1107, in execute_sql
    cursor.execute(sql, params)
  File "/root/.virtualenvs/python3/lib/python3.5/site-packages/django/db/backends/utils.py", line 80, in execute
    return super(CursorDebugWrapper, self).execute(sql, params)
  File "/root/.virtualenvs/python3/lib/python3.5/site-packages/django/db/backends/utils.py", line 65, in execute
    return self.cursor.execute(sql, params)
  File "/root/.virtualenvs/python3/lib/python3.5/site-packages/django/db/utils.py", line 94, in __exit__
    six.reraise(dj_exc_type, dj_exc_value, traceback)
  File "/root/.virtualenvs/python3/lib/python3.5/site-packages/django/utils/six.py", line 685, in reraise
    raise value.with_traceback(tb)
  File "/root/.virtualenvs/python3/lib/python3.5/site-packages/django/db/backends/utils.py", line 65, in execute
    return self.cursor.execute(sql, params)
  File "/root/.virtualenvs/python3/lib/python3.5/site-packages/django/db/backends/mysql/base.py", line 101, in execute
    return self.cursor.execute(query, args)
  File "/root/.virtualenvs/python3/lib/python3.5/site-packages/pymysql/cursors.py", line 170, in execute
    result = self._query(query)
  File "/root/.virtualenvs/python3/lib/python3.5/site-packages/pymysql/cursors.py", line 328, in _query
    conn.query(q)
  File "/root/.virtualenvs/python3/lib/python3.5/site-packages/pymysql/connections.py", line 517, in query
    self._affected_rows = self._read_query_result(unbuffered=unbuffered)
  File "/root/.virtualenvs/python3/lib/python3.5/site-packages/pymysql/connections.py", line 732, in _read_query_result
    result.read()
  File "/root/.virtualenvs/python3/lib/python3.5/site-packages/pymysql/connections.py", line 1075, in read
    first_packet = self.connection._read_packet()
  File "/root/.virtualenvs/python3/lib/python3.5/site-packages/pymysql/connections.py", line 684, in _read_packet
    packet.check_error()
  File "/root/.virtualenvs/python3/lib/python3.5/site-packages/pymysql/protocol.py", line 220, in check_error
    err.raise_mysql_exception(self._data)
  File "/root/.virtualenvs/python3/lib/python3.5/site-packages/pymysql/err.py", line 109, in raise_mysql_exception
    raise errorclass(errno, errval)
django.db.utils.ProgrammingError: (1146, "Table 'python1812axf.app_order' doesn't exist")
[pid: 21815|app: 0|req: 24/24] 113.87.160.176 () {44 vars in 874 bytes} [Wed Mar 13 21:23:30 2019] GET /axf/generateorder/ => generated 199003 bytes in 97 msecs (HTTP/1.1 500) 4 headers in 130 bytes (1 switches on core 0)
Internal Server Error: /axf/generateorder/
Traceback (most recent call last):
  File "/root/.virtualenvs/python3/lib/python3.5/site-packages/django/db/backends/utils.py", line 65, in execute
    return self.cursor.execute(sql, params)
  File "/root/.virtualenvs/python3/lib/python3.5/site-packages/django/db/backends/mysql/base.py", line 101, in execute
    return self.cursor.execute(query, args)
  File "/root/.virtualenvs/python3/lib/python3.5/site-packages/pymysql/cursors.py", line 170, in execute
    result = self._query(query)
  File "/root/.virtualenvs/python3/lib/python3.5/site-packages/pymysql/cursors.py", line 328, in _query
    conn.query(q)
  File "/root/.virtualenvs/python3/lib/python3.5/site-packages/pymysql/connections.py", line 517, in query
    self._affected_rows = self._read_query_result(unbuffered=unbuffered)
  File "/root/.virtualenvs/python3/lib/python3.5/site-packages/pymysql/connections.py", line 732, in _read_query_result
    result.read()
  File "/root/.virtualenvs/python3/lib/python3.5/site-packages/pymysql/connections.py", line 1075, in read
    first_packet = self.connection._read_packet()
  File "/root/.virtualenvs/python3/lib/python3.5/site-packages/pymysql/connections.py", line 684, in _read_packet
    packet.check_error()
  File "/root/.virtualenvs/python3/lib/python3.5/site-packages/pymysql/protocol.py", line 220, in check_error
    err.raise_mysql_exception(self._data)
  File "/root/.virtualenvs/python3/lib/python3.5/site-packages/pymysql/err.py", line 109, in raise_mysql_exception
    raise errorclass(errno, errval)
pymysql.err.ProgrammingError: (1146, "Table 'python1812axf.app_order' doesn't exist")

The above exception was the direct cause of the following exception:

Traceback (most recent call last):
  File "/root/.virtualenvs/python3/lib/python3.5/site-packages/django/core/handlers/exception.py", line 41, in inner
    response = get_response(request)
  File "/root/.virtualenvs/python3/lib/python3.5/site-packages/django/core/handlers/base.py", line 187, in _get_response
    response = self.process_exception_by_middleware(e, request)
  File "/root/.virtualenvs/python3/lib/python3.5/site-packages/django/core/handlers/base.py", line 185, in _get_response
    response = wrapped_callback(request, *callback_args, **callback_kwargs)
  File "./app/views.py", line 385, in generateorder
    order.save()
  File "/root/.virtualenvs/python3/lib/python3.5/site-packages/django/db/models/base.py", line 807, in save
    force_update=force_update, update_fields=update_fields)
  File "/root/.virtualenvs/python3/lib/python3.5/site-packages/django/db/models/base.py", line 837, in save_base
    updated = self._save_table(raw, cls, force_insert, force_update, using, update_fields)
  File "/root/.virtualenvs/python3/lib/python3.5/site-packages/django/db/models/base.py", line 923, in _save_table
    result = self._do_insert(cls._base_manager, using, fields, update_pk, raw)
  File "/root/.virtualenvs/python3/lib/python3.5/site-packages/django/db/models/base.py", line 962, in _do_insert
    using=using, raw=raw)
  File "/root/.virtualenvs/python3/lib/python3.5/site-packages/django/db/models/manager.py", line 85, in manager_method
    return getattr(self.get_queryset(), name)(*args, **kwargs)
  File "/root/.virtualenvs/python3/lib/python3.5/site-packages/django/db/models/query.py", line 1076, in _insert
    return query.get_compiler(using=using).execute_sql(return_id)
  File "/root/.virtualenvs/python3/lib/python3.5/site-packages/django/db/models/sql/compiler.py", line 1107, in execute_sql
    cursor.execute(sql, params)
  File "/root/.virtualenvs/python3/lib/python3.5/site-packages/django/db/backends/utils.py", line 80, in execute
    return super(CursorDebugWrapper, self).execute(sql, params)
  File "/root/.virtualenvs/python3/lib/python3.5/site-packages/django/db/backends/utils.py", line 65, in execute
    return self.cursor.execute(sql, params)
  File "/root/.virtualenvs/python3/lib/python3.5/site-packages/django/db/utils.py", line 94, in __exit__
    six.reraise(dj_exc_type, dj_exc_value, traceback)
  File "/root/.virtualenvs/python3/lib/python3.5/site-packages/django/utils/six.py", line 685, in reraise
    raise value.with_traceback(tb)
  File "/root/.virtualenvs/python3/lib/python3.5/site-packages/django/db/backends/utils.py", line 65, in execute
    return self.cursor.execute(sql, params)
  File "/root/.virtualenvs/python3/lib/python3.5/site-packages/django/db/backends/mysql/base.py", line 101, in execute
    return self.cursor.execute(query, args)
  File "/root/.virtualenvs/python3/lib/python3.5/site-packages/pymysql/cursors.py", line 170, in execute
    result = self._query(query)
  File "/root/.virtualenvs/python3/lib/python3.5/site-packages/pymysql/cursors.py", line 328, in _query
    conn.query(q)
  File "/root/.virtualenvs/python3/lib/python3.5/site-packages/pymysql/connections.py", line 517, in query
    self._affected_rows = self._read_query_result(unbuffered=unbuffered)
  File "/root/.virtualenvs/python3/lib/python3.5/site-packages/pymysql/connections.py", line 732, in _read_query_result
    result.read()
  File "/root/.virtualenvs/python3/lib/python3.5/site-packages/pymysql/connections.py", line 1075, in read
    first_packet = self.connection._read_packet()
  File "/root/.virtualenvs/python3/lib/python3.5/site-packages/pymysql/connections.py", line 684, in _read_packet
    packet.check_error()
  File "/root/.virtualenvs/python3/lib/python3.5/site-packages/pymysql/protocol.py", line 220, in check_error
    err.raise_mysql_exception(self._data)
  File "/root/.virtualenvs/python3/lib/python3.5/site-packages/pymysql/err.py", line 109, in raise_mysql_exception
    raise errorclass(errno, errval)
django.db.utils.ProgrammingError: (1146, "Table 'python1812axf.app_order' doesn't exist")
[pid: 21815|app: 0|req: 25/25] 113.87.160.176 () {44 vars in 874 bytes} [Wed Mar 13 21:23:31 2019] GET /axf/generateorder/ => generated 199018 bytes in 94 msecs (HTTP/1.1 500) 4 headers in 130 bytes (1 switches on core 0)
Internal Server Error: /axf/generateorder/
Traceback (most recent call last):
  File "/root/.virtualenvs/python3/lib/python3.5/site-packages/django/db/backends/utils.py", line 65, in execute
    return self.cursor.execute(sql, params)
  File "/root/.virtualenvs/python3/lib/python3.5/site-packages/django/db/backends/mysql/base.py", line 101, in execute
    return self.cursor.execute(query, args)
  File "/root/.virtualenvs/python3/lib/python3.5/site-packages/pymysql/cursors.py", line 170, in execute
    result = self._query(query)
  File "/root/.virtualenvs/python3/lib/python3.5/site-packages/pymysql/cursors.py", line 328, in _query
    conn.query(q)
  File "/root/.virtualenvs/python3/lib/python3.5/site-packages/pymysql/connections.py", line 517, in query
    self._affected_rows = self._read_query_result(unbuffered=unbuffered)
  File "/root/.virtualenvs/python3/lib/python3.5/site-packages/pymysql/connections.py", line 732, in _read_query_result
    result.read()
  File "/root/.virtualenvs/python3/lib/python3.5/site-packages/pymysql/connections.py", line 1075, in read
    first_packet = self.connection._read_packet()
  File "/root/.virtualenvs/python3/lib/python3.5/site-packages/pymysql/connections.py", line 684, in _read_packet
    packet.check_error()
  File "/root/.virtualenvs/python3/lib/python3.5/site-packages/pymysql/protocol.py", line 220, in check_error
    err.raise_mysql_exception(self._data)
  File "/root/.virtualenvs/python3/lib/python3.5/site-packages/pymysql/err.py", line 109, in raise_mysql_exception
    raise errorclass(errno, errval)
pymysql.err.ProgrammingError: (1146, "Table 'python1812axf.app_order' doesn't exist")

The above exception was the direct cause of the following exception:

Traceback (most recent call last):
  File "/root/.virtualenvs/python3/lib/python3.5/site-packages/django/core/handlers/exception.py", line 41, in inner
    response = get_response(request)
  File "/root/.virtualenvs/python3/lib/python3.5/site-packages/django/core/handlers/base.py", line 187, in _get_response
    response = self.process_exception_by_middleware(e, request)
  File "/root/.virtualenvs/python3/lib/python3.5/site-packages/django/core/handlers/base.py", line 185, in _get_response
    response = wrapped_callback(request, *callback_args, **callback_kwargs)
  File "./app/views.py", line 385, in generateorder
    order.save()
  File "/root/.virtualenvs/python3/lib/python3.5/site-packages/django/db/models/base.py", line 807, in save
    force_update=force_update, update_fields=update_fields)
  File "/root/.virtualenvs/python3/lib/python3.5/site-packages/django/db/models/base.py", line 837, in save_base
    updated = self._save_table(raw, cls, force_insert, force_update, using, update_fields)
  File "/root/.virtualenvs/python3/lib/python3.5/site-packages/django/db/models/base.py", line 923, in _save_table
    result = self._do_insert(cls._base_manager, using, fields, update_pk, raw)
  File "/root/.virtualenvs/python3/lib/python3.5/site-packages/django/db/models/base.py", line 962, in _do_insert
    using=using, raw=raw)
  File "/root/.virtualenvs/python3/lib/python3.5/site-packages/django/db/models/manager.py", line 85, in manager_method
    return getattr(self.get_queryset(), name)(*args, **kwargs)
  File "/root/.virtualenvs/python3/lib/python3.5/site-packages/django/db/models/query.py", line 1076, in _insert
    return query.get_compiler(using=using).execute_sql(return_id)
  File "/root/.virtualenvs/python3/lib/python3.5/site-packages/django/db/models/sql/compiler.py", line 1107, in execute_sql
    cursor.execute(sql, params)
  File "/root/.virtualenvs/python3/lib/python3.5/site-packages/django/db/backends/utils.py", line 80, in execute
    return super(CursorDebugWrapper, self).execute(sql, params)
  File "/root/.virtualenvs/python3/lib/python3.5/site-packages/django/db/backends/utils.py", line 65, in execute
    return self.cursor.execute(sql, params)
  File "/root/.virtualenvs/python3/lib/python3.5/site-packages/django/db/utils.py", line 94, in __exit__
    six.reraise(dj_exc_type, dj_exc_value, traceback)
  File "/root/.virtualenvs/python3/lib/python3.5/site-packages/django/utils/six.py", line 685, in reraise
    raise value.with_traceback(tb)
  File "/root/.virtualenvs/python3/lib/python3.5/site-packages/django/db/backends/utils.py", line 65, in execute
    return self.cursor.execute(sql, params)
  File "/root/.virtualenvs/python3/lib/python3.5/site-packages/django/db/backends/mysql/base.py", line 101, in execute
    return self.cursor.execute(query, args)
  File "/root/.virtualenvs/python3/lib/python3.5/site-packages/pymysql/cursors.py", line 170, in execute
    result = self._query(query)
  File "/root/.virtualenvs/python3/lib/python3.5/site-packages/pymysql/cursors.py", line 328, in _query
    conn.query(q)
  File "/root/.virtualenvs/python3/lib/python3.5/site-packages/pymysql/connections.py", line 517, in query
    self._affected_rows = self._read_query_result(unbuffered=unbuffered)
  File "/root/.virtualenvs/python3/lib/python3.5/site-packages/pymysql/connections.py", line 732, in _read_query_result
    result.read()
  File "/root/.virtualenvs/python3/lib/python3.5/site-packages/pymysql/connections.py", line 1075, in read
    first_packet = self.connection._read_packet()
  File "/root/.virtualenvs/python3/lib/python3.5/site-packages/pymysql/connections.py", line 684, in _read_packet
    packet.check_error()
  File "/root/.virtualenvs/python3/lib/python3.5/site-packages/pymysql/protocol.py", line 220, in check_error
    err.raise_mysql_exception(self._data)
  File "/root/.virtualenvs/python3/lib/python3.5/site-packages/pymysql/err.py", line 109, in raise_mysql_exception
    raise errorclass(errno, errval)
django.db.utils.ProgrammingError: (1146, "Table 'python1812axf.app_order' doesn't exist")
[pid: 21815|app: 0|req: 26/26] 113.87.160.176 () {44 vars in 874 bytes} [Wed Mar 13 21:23:32 2019] GET /axf/generateorder/ => generated 199017 bytes in 96 msecs (HTTP/1.1 500) 4 headers in 130 bytes (1 switches on core 0)
Internal Server Error: /axf/generateorder/
Traceback (most recent call last):
  File "/root/.virtualenvs/python3/lib/python3.5/site-packages/django/db/backends/utils.py", line 65, in execute
    return self.cursor.execute(sql, params)
  File "/root/.virtualenvs/python3/lib/python3.5/site-packages/django/db/backends/mysql/base.py", line 101, in execute
    return self.cursor.execute(query, args)
  File "/root/.virtualenvs/python3/lib/python3.5/site-packages/pymysql/cursors.py", line 170, in execute
    result = self._query(query)
  File "/root/.virtualenvs/python3/lib/python3.5/site-packages/pymysql/cursors.py", line 328, in _query
    conn.query(q)
  File "/root/.virtualenvs/python3/lib/python3.5/site-packages/pymysql/connections.py", line 517, in query
    self._affected_rows = self._read_query_result(unbuffered=unbuffered)
  File "/root/.virtualenvs/python3/lib/python3.5/site-packages/pymysql/connections.py", line 732, in _read_query_result
    result.read()
  File "/root/.virtualenvs/python3/lib/python3.5/site-packages/pymysql/connections.py", line 1075, in read
    first_packet = self.connection._read_packet()
  File "/root/.virtualenvs/python3/lib/python3.5/site-packages/pymysql/connections.py", line 684, in _read_packet
    packet.check_error()
  File "/root/.virtualenvs/python3/lib/python3.5/site-packages/pymysql/protocol.py", line 220, in check_error
    err.raise_mysql_exception(self._data)
  File "/root/.virtualenvs/python3/lib/python3.5/site-packages/pymysql/err.py", line 109, in raise_mysql_exception
    raise errorclass(errno, errval)
pymysql.err.ProgrammingError: (1146, "Table 'python1812axf.app_order' doesn't exist")

The above exception was the direct cause of the following exception:

Traceback (most recent call last):
  File "/root/.virtualenvs/python3/lib/python3.5/site-packages/django/core/handlers/exception.py", line 41, in inner
    response = get_response(request)
  File "/root/.virtualenvs/python3/lib/python3.5/site-packages/django/core/handlers/base.py", line 187, in _get_response
    response = self.process_exception_by_middleware(e, request)
  File "/root/.virtualenvs/python3/lib/python3.5/site-packages/django/core/handlers/base.py", line 185, in _get_response
    response = wrapped_callback(request, *callback_args, **callback_kwargs)
  File "./app/views.py", line 385, in generateorder
    order.save()
  File "/root/.virtualenvs/python3/lib/python3.5/site-packages/django/db/models/base.py", line 807, in save
    force_update=force_update, update_fields=update_fields)
  File "/root/.virtualenvs/python3/lib/python3.5/site-packages/django/db/models/base.py", line 837, in save_base
    updated = self._save_table(raw, cls, force_insert, force_update, using, update_fields)
  File "/root/.virtualenvs/python3/lib/python3.5/site-packages/django/db/models/base.py", line 923, in _save_table
    result = self._do_insert(cls._base_manager, using, fields, update_pk, raw)
  File "/root/.virtualenvs/python3/lib/python3.5/site-packages/django/db/models/base.py", line 962, in _do_insert
    using=using, raw=raw)
  File "/root/.virtualenvs/python3/lib/python3.5/site-packages/django/db/models/manager.py", line 85, in manager_method
    return getattr(self.get_queryset(), name)(*args, **kwargs)
  File "/root/.virtualenvs/python3/lib/python3.5/site-packages/django/db/models/query.py", line 1076, in _insert
    return query.get_compiler(using=using).execute_sql(return_id)
  File "/root/.virtualenvs/python3/lib/python3.5/site-packages/django/db/models/sql/compiler.py", line 1107, in execute_sql
    cursor.execute(sql, params)
  File "/root/.virtualenvs/python3/lib/python3.5/site-packages/django/db/backends/utils.py", line 80, in execute
    return super(CursorDebugWrapper, self).execute(sql, params)
  File "/root/.virtualenvs/python3/lib/python3.5/site-packages/django/db/backends/utils.py", line 65, in execute
    return self.cursor.execute(sql, params)
  File "/root/.virtualenvs/python3/lib/python3.5/site-packages/django/db/utils.py", line 94, in __exit__
    six.reraise(dj_exc_type, dj_exc_value, traceback)
  File "/root/.virtualenvs/python3/lib/python3.5/site-packages/django/utils/six.py", line 685, in reraise
    raise value.with_traceback(tb)
  File "/root/.virtualenvs/python3/lib/python3.5/site-packages/django/db/backends/utils.py", line 65, in execute
    return self.cursor.execute(sql, params)
  File "/root/.virtualenvs/python3/lib/python3.5/site-packages/django/db/backends/mysql/base.py", line 101, in execute
    return self.cursor.execute(query, args)
  File "/root/.virtualenvs/python3/lib/python3.5/site-packages/pymysql/cursors.py", line 170, in execute
    result = self._query(query)
  File "/root/.virtualenvs/python3/lib/python3.5/site-packages/pymysql/cursors.py", line 328, in _query
    conn.query(q)
  File "/root/.virtualenvs/python3/lib/python3.5/site-packages/pymysql/connections.py", line 517, in query
    self._affected_rows = self._read_query_result(unbuffered=unbuffered)
  File "/root/.virtualenvs/python3/lib/python3.5/site-packages/pymysql/connections.py", line 732, in _read_query_result
    result.read()
  File "/root/.virtualenvs/python3/lib/python3.5/site-packages/pymysql/connections.py", line 1075, in read
    first_packet = self.connection._read_packet()
  File "/root/.virtualenvs/python3/lib/python3.5/site-packages/pymysql/connections.py", line 684, in _read_packet
    packet.check_error()
  File "/root/.virtualenvs/python3/lib/python3.5/site-packages/pymysql/protocol.py", line 220, in check_error
    err.raise_mysql_exception(self._data)
  File "/root/.virtualenvs/python3/lib/python3.5/site-packages/pymysql/err.py", line 109, in raise_mysql_exception
    raise errorclass(errno, errval)
django.db.utils.ProgrammingError: (1146, "Table 'python1812axf.app_order' doesn't exist")
[pid: 21815|app: 0|req: 27/27] 113.87.160.176 () {44 vars in 874 bytes} [Wed Mar 13 21:23:33 2019] GET /axf/generateorder/ => generated 199017 bytes in 94 msecs (HTTP/1.1 500) 4 headers in 130 bytes (1 switches on core 0)
Internal Server Error: /axf/generateorder/
Traceback (most recent call last):
  File "/root/.virtualenvs/python3/lib/python3.5/site-packages/django/db/backends/utils.py", line 65, in execute
    return self.cursor.execute(sql, params)
  File "/root/.virtualenvs/python3/lib/python3.5/site-packages/django/db/backends/mysql/base.py", line 101, in execute
    return self.cursor.execute(query, args)
  File "/root/.virtualenvs/python3/lib/python3.5/site-packages/pymysql/cursors.py", line 170, in execute
    result = self._query(query)
  File "/root/.virtualenvs/python3/lib/python3.5/site-packages/pymysql/cursors.py", line 328, in _query
    conn.query(q)
  File "/root/.virtualenvs/python3/lib/python3.5/site-packages/pymysql/connections.py", line 517, in query
    self._affected_rows = self._read_query_result(unbuffered=unbuffered)
  File "/root/.virtualenvs/python3/lib/python3.5/site-packages/pymysql/connections.py", line 732, in _read_query_result
    result.read()
  File "/root/.virtualenvs/python3/lib/python3.5/site-packages/pymysql/connections.py", line 1075, in read
    first_packet = self.connection._read_packet()
  File "/root/.virtualenvs/python3/lib/python3.5/site-packages/pymysql/connections.py", line 684, in _read_packet
    packet.check_error()
  File "/root/.virtualenvs/python3/lib/python3.5/site-packages/pymysql/protocol.py", line 220, in check_error
    err.raise_mysql_exception(self._data)
  File "/root/.virtualenvs/python3/lib/python3.5/site-packages/pymysql/err.py", line 109, in raise_mysql_exception
    raise errorclass(errno, errval)
pymysql.err.ProgrammingError: (1146, "Table 'python1812axf.app_order' doesn't exist")

The above exception was the direct cause of the following exception:

Traceback (most recent call last):
  File "/root/.virtualenvs/python3/lib/python3.5/site-packages/django/core/handlers/exception.py", line 41, in inner
    response = get_response(request)
  File "/root/.virtualenvs/python3/lib/python3.5/site-packages/django/core/handlers/base.py", line 187, in _get_response
    response = self.process_exception_by_middleware(e, request)
  File "/root/.virtualenvs/python3/lib/python3.5/site-packages/django/core/handlers/base.py", line 185, in _get_response
    response = wrapped_callback(request, *callback_args, **callback_kwargs)
  File "./app/views.py", line 385, in generateorder
    order.save()
  File "/root/.virtualenvs/python3/lib/python3.5/site-packages/django/db/models/base.py", line 807, in save
    force_update=force_update, update_fields=update_fields)
  File "/root/.virtualenvs/python3/lib/python3.5/site-packages/django/db/models/base.py", line 837, in save_base
    updated = self._save_table(raw, cls, force_insert, force_update, using, update_fields)
  File "/root/.virtualenvs/python3/lib/python3.5/site-packages/django/db/models/base.py", line 923, in _save_table
    result = self._do_insert(cls._base_manager, using, fields, update_pk, raw)
  File "/root/.virtualenvs/python3/lib/python3.5/site-packages/django/db/models/base.py", line 962, in _do_insert
    using=using, raw=raw)
  File "/root/.virtualenvs/python3/lib/python3.5/site-packages/django/db/models/manager.py", line 85, in manager_method
    return getattr(self.get_queryset(), name)(*args, **kwargs)
  File "/root/.virtualenvs/python3/lib/python3.5/site-packages/django/db/models/query.py", line 1076, in _insert
    return query.get_compiler(using=using).execute_sql(return_id)
  File "/root/.virtualenvs/python3/lib/python3.5/site-packages/django/db/models/sql/compiler.py", line 1107, in execute_sql
    cursor.execute(sql, params)
  File "/root/.virtualenvs/python3/lib/python3.5/site-packages/django/db/backends/utils.py", line 80, in execute
    return super(CursorDebugWrapper, self).execute(sql, params)
  File "/root/.virtualenvs/python3/lib/python3.5/site-packages/django/db/backends/utils.py", line 65, in execute
    return self.cursor.execute(sql, params)
  File "/root/.virtualenvs/python3/lib/python3.5/site-packages/django/db/utils.py", line 94, in __exit__
    six.reraise(dj_exc_type, dj_exc_value, traceback)
  File "/root/.virtualenvs/python3/lib/python3.5/site-packages/django/utils/six.py", line 685, in reraise
    raise value.with_traceback(tb)
  File "/root/.virtualenvs/python3/lib/python3.5/site-packages/django/db/backends/utils.py", line 65, in execute
    return self.cursor.execute(sql, params)
  File "/root/.virtualenvs/python3/lib/python3.5/site-packages/django/db/backends/mysql/base.py", line 101, in execute
    return self.cursor.execute(query, args)
  File "/root/.virtualenvs/python3/lib/python3.5/site-packages/pymysql/cursors.py", line 170, in execute
    result = self._query(query)
  File "/root/.virtualenvs/python3/lib/python3.5/site-packages/pymysql/cursors.py", line 328, in _query
    conn.query(q)
  File "/root/.virtualenvs/python3/lib/python3.5/site-packages/pymysql/connections.py", line 517, in query
    self._affected_rows = self._read_query_result(unbuffered=unbuffered)
  File "/root/.virtualenvs/python3/lib/python3.5/site-packages/pymysql/connections.py", line 732, in _read_query_result
    result.read()
  File "/root/.virtualenvs/python3/lib/python3.5/site-packages/pymysql/connections.py", line 1075, in read
    first_packet = self.connection._read_packet()
  File "/root/.virtualenvs/python3/lib/python3.5/site-packages/pymysql/connections.py", line 684, in _read_packet
    packet.check_error()
  File "/root/.virtualenvs/python3/lib/python3.5/site-packages/pymysql/protocol.py", line 220, in check_error
    err.raise_mysql_exception(self._data)
  File "/root/.virtualenvs/python3/lib/python3.5/site-packages/pymysql/err.py", line 109, in raise_mysql_exception
    raise errorclass(errno, errval)
django.db.utils.ProgrammingError: (1146, "Table 'python1812axf.app_order' doesn't exist")
[pid: 21815|app: 0|req: 28/28] 113.87.160.176 () {44 vars in 874 bytes} [Wed Mar 13 21:23:36 2019] GET /axf/generateorder/ => generated 199002 bytes in 100 msecs (HTTP/1.1 500) 4 headers in 130 bytes (1 switches on core 0)
*** Starting uWSGI 2.0.18 (64bit) on [Wed Mar 13 21:32:07 2019] ***
compiled with version: 5.4.0 20160609 on 13 March 2019 08:00:41
os: Linux-4.4.0-142-generic #168-Ubuntu SMP Wed Jan 16 21:00:45 UTC 2019
nodename: iZwz98nqijeqfo9ffbtx0zZ
machine: x86_64
clock source: unix
detected number of CPU cores: 1
current working directory: /var/www/axf
writing pidfile to uwsgi.pid
detected binary path: /root/.virtualenvs/python3/bin/uwsgi
!!! no internal routing support, rebuild with pcre support !!!
uWSGI running as root, you can use --uid/--gid/--chroot options
*** WARNING: you are running uWSGI as root !!! (use the --uid flag) *** 
chdir() to /var/www/axf
*** WARNING: you are running uWSGI without its master process manager ***
your processes number limit is 3817
your memory page size is 4096 bytes
detected max file descriptor number: 65535
lock engine: pthread robust mutexes
thunder lock: disabled (you can enable it with --thunder-lock)
uwsgi socket 0 bound to TCP address 0.0.0.0:8030 fd 3
uWSGI running as root, you can use --uid/--gid/--chroot options
*** WARNING: you are running uWSGI as root !!! (use the --uid flag) *** 
Python version: 3.5.2 (default, Nov 12 2018, 13:43:14)  [GCC 5.4.0 20160609]
*** Python threads support is disabled. You can enable it with --enable-threads ***
Python main interpreter initialized at 0xa9e4b0
uWSGI running as root, you can use --uid/--gid/--chroot options
*** WARNING: you are running uWSGI as root !!! (use the --uid flag) *** 
your server socket listen backlog is limited to 100 connections
your mercy for graceful operations on workers is 60 seconds
mapped 72904 bytes (71 KB) for 1 cores
*** Operational MODE: single process ***
WSGI app 0 (mountpoint='') ready in 1 seconds on interpreter 0xa9e4b0 pid: 21870 (default app)
uWSGI running as root, you can use --uid/--gid/--chroot options
*** WARNING: you are running uWSGI as root !!! (use the --uid flag) *** 
*** uWSGI is running in multiple interpreter mode ***
spawned uWSGI worker 1 (and the only) (pid: 21870, cores: 1)
Internal Server Error: /axf/generateorder/
Traceback (most recent call last):
  File "/root/.virtualenvs/python3/lib/python3.5/site-packages/django/core/handlers/exception.py", line 41, in inner
    response = get_response(request)
  File "/root/.virtualenvs/python3/lib/python3.5/site-packages/django/core/handlers/base.py", line 187, in _get_response
    response = self.process_exception_by_middleware(e, request)
  File "/root/.virtualenvs/python3/lib/python3.5/site-packages/django/core/handlers/base.py", line 185, in _get_response
    response = wrapped_callback(request, *callback_args, **callback_kwargs)
  File "./app/views.py", line 379, in generateorder
    user = User.objects.get(pk=userid)
  File "/root/.virtualenvs/python3/lib/python3.5/site-packages/django/db/models/manager.py", line 85, in manager_method
    return getattr(self.get_queryset(), name)(*args, **kwargs)
  File "/root/.virtualenvs/python3/lib/python3.5/site-packages/django/db/models/query.py", line 380, in get
    self.model._meta.object_name
app.models.DoesNotExist: User matching query does not exist.
[pid: 21870|app: 0|req: 1/1] 113.87.160.176 () {44 vars in 874 bytes} [Wed Mar 13 21:32:12 2019] GET /axf/generateorder/ => generated 68643 bytes in 103 msecs (HTTP/1.1 500) 4 headers in 200 bytes (1 switches on core 0)
Internal Server Error: /axf/generateorder/
Traceback (most recent call last):
  File "/root/.virtualenvs/python3/lib/python3.5/site-packages/django/core/handlers/exception.py", line 41, in inner
    response = get_response(request)
  File "/root/.virtualenvs/python3/lib/python3.5/site-packages/django/core/handlers/base.py", line 187, in _get_response
    response = self.process_exception_by_middleware(e, request)
  File "/root/.virtualenvs/python3/lib/python3.5/site-packages/django/core/handlers/base.py", line 185, in _get_response
    response = wrapped_callback(request, *callback_args, **callback_kwargs)
  File "./app/views.py", line 379, in generateorder
    user = User.objects.get(pk=userid)
  File "/root/.virtualenvs/python3/lib/python3.5/site-packages/django/db/models/manager.py", line 85, in manager_method
    return getattr(self.get_queryset(), name)(*args, **kwargs)
  File "/root/.virtualenvs/python3/lib/python3.5/site-packages/django/db/models/query.py", line 380, in get
    self.model._meta.object_name
app.models.DoesNotExist: User matching query does not exist.
[pid: 21870|app: 0|req: 2/2] 113.87.160.176 () {44 vars in 830 bytes} [Wed Mar 13 21:32:25 2019] GET /axf/generateorder/ => generated 68428 bytes in 43 msecs (HTTP/1.1 500) 4 headers in 129 bytes (1 switches on core 0)
[pid: 21870|app: 0|req: 3/3] 113.87.160.176 () {42 vars in 771 bytes} [Wed Mar 13 21:32:28 2019] GET /axf/ => generated 21767 bytes in 33 msecs (HTTP/1.1 200) 3 headers in 111 bytes (1 switches on core 0)
[pid: 21870|app: 0|req: 4/4] 113.87.160.176 () {44 vars in 823 bytes} [Wed Mar 13 21:32:30 2019] GET /axf/mine/ => generated 6232 bytes in 5 msecs (HTTP/1.1 200) 4 headers in 124 bytes (1 switches on core 0)
[pid: 21870|app: 0|req: 5/5] 113.87.160.176 () {44 vars in 828 bytes} [Wed Mar 13 21:32:33 2019] GET /axf/login/ => generated 2138 bytes in 4 msecs (HTTP/1.1 200) 5 headers in 278 bytes (1 switches on core 0)
123123@qq.com 123123
[pid: 21870|app: 0|req: 6/6] 113.87.160.176 () {52 vars in 1013 bytes} [Wed Mar 13 21:32:38 2019] POST /axf/login/ => generated 0 bytes in 11 msecs (HTTP/1.1 302) 6 headers in 277 bytes (1 switches on core 0)
[pid: 21870|app: 0|req: 7/7] 113.87.160.176 () {46 vars in 902 bytes} [Wed Mar 13 21:32:38 2019] GET /axf/mine/ => generated 6346 bytes in 12 msecs (HTTP/1.1 200) 4 headers in 124 bytes (1 switches on core 0)
[pid: 21870|app: 0|req: 8/8] 113.87.160.176 () {44 vars in 870 bytes} [Wed Mar 13 21:32:54 2019] GET /axf/cart/ => generated 2737 bytes in 10 msecs (HTTP/1.1 200) 4 headers in 124 bytes (1 switches on core 0)
[pid: 21870|app: 0|req: 9/9] 113.87.160.176 () {44 vars in 874 bytes} [Wed Mar 13 21:32:56 2019] GET /axf/market/ => generated 11361 bytes in 18 msecs (HTTP/1.1 200) 4 headers in 125 bytes (1 switches on core 0)
[pid: 21870|app: 0|req: 10/10] 113.87.160.176 () {44 vars in 885 bytes} [Wed Mar 13 21:32:58 2019] GET /axf/market/ => generated 43231 bytes in 23 msecs (HTTP/1.1 200) 4 headers in 125 bytes (1 switches on core 0)
[pid: 21870|app: 0|req: 11/11] 113.87.160.176 () {44 vars in 832 bytes} [Wed Mar 13 21:32:59 2019] GET /axf/addcart/?goodsid=531 => generated 153 bytes in 11 msecs (HTTP/1.1 200) 4 headers in 115 bytes (1 switches on core 0)
[pid: 21870|app: 0|req: 12/12] 113.87.160.176 () {44 vars in 832 bytes} [Wed Mar 13 21:33:00 2019] GET /axf/addcart/?goodsid=532 => generated 159 bytes in 11 msecs (HTTP/1.1 200) 4 headers in 115 bytes (1 switches on core 0)
[pid: 21870|app: 0|req: 13/13] 113.87.160.176 () {44 vars in 881 bytes} [Wed Mar 13 21:33:01 2019] GET /axf/cart/ => generated 4468 bytes in 15 msecs (HTTP/1.1 200) 4 headers in 124 bytes (1 switches on core 0)
[pid: 21870|app: 0|req: 14/14] 113.87.160.176 () {44 vars in 897 bytes} [Wed Mar 13 21:33:05 2019] GET /axf/generateorder/ => generated 1497 bytes in 40 msecs (HTTP/1.1 200) 4 headers in 124 bytes (1 switches on core 0)
[pid: 21870|app: 0|req: 15/15] 113.87.160.176 () {44 vars in 879 bytes} [Wed Mar 13 21:33:35 2019] GET /axf/mine/ => generated 6347 bytes in 11 msecs (HTTP/1.1 200) 4 headers in 124 bytes (1 switches on core 0)
[pid: 21870|app: 0|req: 16/16] 113.87.160.176 () {44 vars in 889 bytes} [Wed Mar 13 21:33:42 2019] GET /axf/orderlist/ => generated 4553 bytes in 12 msecs (HTTP/1.1 200) 4 headers in 124 bytes (1 switches on core 0)
[pid: 21870|app: 0|req: 17/17] 113.87.160.176 () {44 vars in 942 bytes} [Wed Mar 13 21:33:45 2019] GET /axf/orderdetail/1552474838.9925752255/ => generated 1961 bytes in 16 msecs (HTTP/1.1 200) 3 headers in 110 bytes (1 switches on core 0)
[pid: 21870|app: 0|req: 18/18] 113.87.160.176 () {44 vars in 942 bytes} [Wed Mar 13 21:33:53 2019] GET /axf/orderdetail/1552475029.9817135518/ => generated 1684 bytes in 12 msecs (HTTP/1.1 200) 3 headers in 110 bytes (1 switches on core 0)
[pid: 21870|app: 0|req: 19/19] 113.87.160.176 () {44 vars in 889 bytes} [Wed Mar 13 21:34:14 2019] GET /axf/orderlist/ => generated 4553 bytes in 11 msecs (HTTP/1.1 200) 4 headers in 124 bytes (1 switches on core 0)
[pid: 21870|app: 0|req: 20/20] 113.87.160.176 () {44 vars in 942 bytes} [Wed Mar 13 21:34:17 2019] GET /axf/orderdetail/1552480539.0409161833/ => generated 1499 bytes in 12 msecs (HTTP/1.1 200) 3 headers in 110 bytes (1 switches on core 0)
[pid: 21870|app: 0|req: 21/21] 113.87.160.176 () {44 vars in 863 bytes} [Wed Mar 13 21:34:45 2019] GET /axf/mine/ => generated 6347 bytes in 14 msecs (HTTP/1.1 200) 4 headers in 124 bytes (1 switches on core 0)
[pid: 21870|app: 0|req: 22/22] 113.87.160.176 () {44 vars in 879 bytes} [Wed Mar 13 21:35:01 2019] GET /axf/cart/ => generated 2737 bytes in 11 msecs (HTTP/1.1 200) 4 headers in 124 bytes (1 switches on core 0)
[pid: 21870|app: 0|req: 23/23] 113.87.160.176 () {44 vars in 883 bytes} [Wed Mar 13 21:35:06 2019] GET /axf/market/ => generated 43231 bytes in 23 msecs (HTTP/1.1 200) 4 headers in 125 bytes (1 switches on core 0)
[pid: 21870|app: 0|req: 24/24] 113.87.160.176 () {44 vars in 881 bytes} [Wed Mar 13 21:35:11 2019] GET /axf/mine/ => generated 6347 bytes in 12 msecs (HTTP/1.1 200) 4 headers in 124 bytes (1 switches on core 0)
[pid: 21870|app: 0|req: 25/25] 113.87.160.176 () {44 vars in 863 bytes} [Wed Mar 13 21:35:22 2019] GET /axf/mine/ => generated 6347 bytes in 11 msecs (HTTP/1.1 200) 4 headers in 124 bytes (1 switches on core 0)
[pid: 21870|app: 0|req: 26/26] 113.87.160.176 () {44 vars in 863 bytes} [Wed Mar 13 21:35:32 2019] GET /axf/mine/ => generated 6347 bytes in 11 msecs (HTTP/1.1 200) 4 headers in 124 bytes (1 switches on core 0)
[pid: 21870|app: 0|req: 27/27] 113.87.160.176 () {44 vars in 889 bytes} [Wed Mar 13 21:35:41 2019] GET /axf/orderlist/ => generated 4553 bytes in 11 msecs (HTTP/1.1 200) 4 headers in 124 bytes (1 switches on core 0)
[pid: 21870|app: 0|req: 28/28] 113.87.160.176 () {44 vars in 942 bytes} [Wed Mar 13 21:35:42 2019] GET /axf/orderdetail/1552474838.9925752255/ => generated 1961 bytes in 15 msecs (HTTP/1.1 200) 3 headers in 110 bytes (1 switches on core 0)
Not Found: /acadmin.php
[pid: 21870|app: 0|req: 29/29] 198.167.223.52 () {36 vars in 579 bytes} [Wed Mar 13 21:46:57 2019] GET /acadmin.php => generated 2070 bytes in 3 msecs (HTTP/1.1 404) 3 headers in 102 bytes (1 switches on core 0)
Not Found: /cache/global/img/gs.gif
[pid: 21870|app: 0|req: 30/30] 80.82.70.187 () {32 vars in 414 bytes} [Wed Mar 13 21:53:25 2019] GET /cache/global/img/gs.gif => generated 2105 bytes in 3 msecs (HTTP/1.1 404) 3 headers in 102 bytes (1 switches on core 0)
Invalid HTTP_HOST header: ''. The domain name provided is not valid according to RFC 1034/1035.
[pid: 21870|app: 0|req: 31/31] 114.34.147.80 () {26 vars in 262 bytes} [Wed Mar 13 21:55:29 2019] GET / => generated 55189 bytes in 31 msecs (HTTP/1.0 400) 1 headers in 53 bytes (1 switches on core 0)
Not Found: /v1/agent/self
[pid: 21870|app: 0|req: 32/32] 95.117.116.93 () {28 vars in 310 bytes} [Wed Mar 13 23:51:37 2019] GET /v1/agent/self => generated 2071 bytes in 4 msecs (HTTP/1.1 404) 3 headers in 102 bytes (1 switches on core 0)
Not Found: /
[pid: 21870|app: 0|req: 33/33] 106.14.120.193 () {34 vars in 462 bytes} [Thu Mar 14 00:08:06 2019] GET / => generated 2019 bytes in 3 msecs (HTTP/1.1 404) 3 headers in 102 bytes (1 switches on core 0)
Not Found: /
[pid: 21870|app: 0|req: 34/34] 177.188.51.36 () {32 vars in 446 bytes} [Thu Mar 14 00:32:49 2019] GET / => generated 2022 bytes in 3 msecs (HTTP/1.1 404) 3 headers in 102 bytes (1 switches on core 0)
Not Found: /
[pid: 21870|app: 0|req: 35/35] 177.188.51.36 () {32 vars in 445 bytes} [Thu Mar 14 00:32:49 2019] GET / => generated 2022 bytes in 3 msecs (HTTP/1.1 404) 3 headers in 102 bytes (1 switches on core 0)
Invalid HTTP_HOST header: ''. The domain name provided is not valid according to RFC 1034/1035.
[pid: 21870|app: 0|req: 36/36] 50.249.177.140 () {26 vars in 263 bytes} [Thu Mar 14 01:07:35 2019] GET / => generated 55190 bytes in 35 msecs (HTTP/1.0 400) 1 headers in 53 bytes (1 switches on core 0)
Not Found: /
[pid: 21870|app: 0|req: 37/37] 107.6.169.250 () {34 vars in 464 bytes} [Thu Mar 14 02:23:08 2019] GET / => generated 2019 bytes in 3 msecs (HTTP/1.1 404) 3 headers in 102 bytes (1 switches on core 0)
Not Found: /
[pid: 21870|app: 0|req: 38/38] 201.150.151.234 () {32 vars in 447 bytes} [Thu Mar 14 06:12:50 2019] GET / => generated 2022 bytes in 3 msecs (HTTP/1.1 404) 3 headers in 102 bytes (1 switches on core 0)
Not Found: /
[pid: 21870|app: 0|req: 39/39] 187.10.187.159 () {32 vars in 446 bytes} [Thu Mar 14 06:13:54 2019] GET / => generated 2022 bytes in 3 msecs (HTTP/1.1 404) 3 headers in 102 bytes (1 switches on core 0)
Not Found: /cache/global/img/gs.gif
[pid: 21870|app: 0|req: 40/40] 80.82.70.187 () {32 vars in 414 bytes} [Thu Mar 14 07:56:28 2019] GET /cache/global/img/gs.gif => generated 2105 bytes in 3 msecs (HTTP/1.1 404) 3 headers in 102 bytes (1 switches on core 0)
Not Found: /
[pid: 21870|app: 0|req: 41/41] 185.129.201.158 () {32 vars in 448 bytes} [Thu Mar 14 08:39:16 2019] GET / => generated 2022 bytes in 3 msecs (HTTP/1.1 404) 3 headers in 102 bytes (1 switches on core 0)
Invalid HTTP_HOST header: ''. The domain name provided is not valid according to RFC 1034/1035.
[pid: 21870|app: 0|req: 42/42] 47.96.254.10 () {26 vars in 261 bytes} [Thu Mar 14 08:44:35 2019] GET / => generated 55188 bytes in 33 msecs (HTTP/1.0 400) 1 headers in 53 bytes (1 switches on core 0)
Invalid HTTP_HOST header: ''. The domain name provided is not valid according to RFC 1034/1035.
[pid: 21870|app: 0|req: 43/43] 216.245.197.254 () {26 vars in 285 bytes} [Thu Mar 14 09:03:50 2019] HEAD /robots.txt => generated 55318 bytes in 33 msecs (HTTP/1.0 400) 1 headers in 53 bytes (1 switches on core 0)
[pid: 21870|app: 0|req: 44/44] 39.107.126.72 () {34 vars in 556 bytes} [Thu Mar 14 09:24:34 2019] GET /axf/orderdetail/1552480539.0409161833/ => generated 1499 bytes in 11 msecs (HTTP/1.1 200) 3 headers in 110 bytes (1 switches on core 0)
Invalid HTTP_HOST header: ''. The domain name provided is not valid according to RFC 1034/1035.
[pid: 21870|app: 0|req: 45/45] 188.190.101.165 () {26 vars in 264 bytes} [Thu Mar 14 09:55:58 2019] GET / => generated 55191 bytes in 32 msecs (HTTP/1.0 400) 1 headers in 53 bytes (1 switches on core 0)
Not Found: /
[pid: 21870|app: 0|req: 46/46] 94.102.49.193 () {34 vars in 518 bytes} [Thu Mar 14 10:18:19 2019] GET / => generated 2019 bytes in 3 msecs (HTTP/1.1 404) 3 headers in 102 bytes (1 switches on core 0)
Not Found: /robots.txt
[pid: 21870|app: 0|req: 47/47] 94.102.49.193 () {30 vars in 341 bytes} [Thu Mar 14 10:18:24 2019] GET /robots.txt => generated 2067 bytes in 3 msecs (HTTP/1.1 404) 3 headers in 102 bytes (1 switches on core 0)
Not Found: /sitemap.xml
[pid: 21870|app: 0|req: 48/48] 94.102.49.193 () {30 vars in 343 bytes} [Thu Mar 14 10:18:31 2019] GET /sitemap.xml => generated 2070 bytes in 3 msecs (HTTP/1.1 404) 3 headers in 102 bytes (1 switches on core 0)
Not Found: /.well-known/security.txt
[pid: 21870|app: 0|req: 49/49] 94.102.49.193 () {30 vars in 369 bytes} [Thu Mar 14 10:18:35 2019] GET /.well-known/security.txt => generated 2109 bytes in 3 msecs (HTTP/1.1 404) 3 headers in 102 bytes (1 switches on core 0)
Not Found: /favicon.ico
[pid: 21870|app: 0|req: 50/50] 94.102.49.193 () {36 vars in 436 bytes} [Thu Mar 14 10:18:42 2019] GET /favicon.ico => generated 2070 bytes in 3 msecs (HTTP/1.1 404) 3 headers in 102 bytes (1 switches on core 0)
Invalid HTTP_HOST header: ''. The domain name provided is not valid according to RFC 1034/1035.
[pid: 21870|app: 0|req: 51/51] 39.107.14.208 () {26 vars in 262 bytes} [Thu Mar 14 10:30:06 2019] GET / => generated 55189 bytes in 30 msecs (HTTP/1.0 400) 1 headers in 53 bytes (1 switches on core 0)
Internal Server Error: /axf/generateorder/
Traceback (most recent call last):
  File "/root/.virtualenvs/python3/lib/python3.5/site-packages/django/core/handlers/exception.py", line 41, in inner
    response = get_response(request)
  File "/root/.virtualenvs/python3/lib/python3.5/site-packages/django/core/handlers/base.py", line 187, in _get_response
    response = self.process_exception_by_middleware(e, request)
  File "/root/.virtualenvs/python3/lib/python3.5/site-packages/django/core/handlers/base.py", line 185, in _get_response
    response = wrapped_callback(request, *callback_args, **callback_kwargs)
  File "./app/views.py", line 379, in generateorder
    user = User.objects.get(pk=userid)
  File "/root/.virtualenvs/python3/lib/python3.5/site-packages/django/db/models/manager.py", line 85, in manager_method
    return getattr(self.get_queryset(), name)(*args, **kwargs)
  File "/root/.virtualenvs/python3/lib/python3.5/site-packages/django/db/models/query.py", line 380, in get
    self.model._meta.object_name
app.models.DoesNotExist: User matching query does not exist.
[pid: 21870|app: 0|req: 52/52] 47.100.38.232 () {34 vars in 516 bytes} [Thu Mar 14 11:44:25 2019] GET /axf/generateorder/ => generated 66906 bytes in 39 msecs (HTTP/1.1 500) 4 headers in 129 bytes (1 switches on core 0)
[pid: 21870|app: 0|req: 53/53] 47.92.2.67 () {34 vars in 553 bytes} [Thu Mar 14 11:44:58 2019] GET /axf/orderdetail/1552475029.9817135518/ => generated 1684 bytes in 12 msecs (HTTP/1.1 200) 3 headers in 110 bytes (1 switches on core 0)
[pid: 21870|app: 0|req: 54/54] 139.224.11.233 () {34 vars in 499 bytes} [Thu Mar 14 11:50:07 2019] GET /axf/mine/ => generated 6232 bytes in 6 msecs (HTTP/1.1 200) 4 headers in 124 bytes (1 switches on core 0)
[pid: 21870|app: 0|req: 55/55] 106.14.115.254 () {34 vars in 499 bytes} [Thu Mar 14 12:18:26 2019] GET /axf/cart/ => generated 2059 bytes in 4 msecs (HTTP/1.1 200) 4 headers in 124 bytes (1 switches on core 0)
[pid: 21870|app: 0|req: 56/56] 47.92.141.208 () {34 vars in 486 bytes} [Thu Mar 14 12:23:32 2019] GET /axf => generated 0 bytes in 0 msecs (HTTP/1.1 301) 3 headers in 110 bytes (1 switches on core 0)
[pid: 21870|app: 0|req: 57/57] 47.92.141.208 () {34 vars in 488 bytes} [Thu Mar 14 12:23:32 2019] GET /axf/ => generated 21767 bytes in 18 msecs (HTTP/1.1 200) 3 headers in 111 bytes (1 switches on core 0)
Not Found: /
[pid: 21870|app: 0|req: 58/58] 106.15.176.145 () {34 vars in 481 bytes} [Thu Mar 14 12:26:17 2019] GET / => generated 2019 bytes in 4 msecs (HTTP/1.1 404) 3 headers in 102 bytes (1 switches on core 0)
Not Found: /
[pid: 21870|app: 0|req: 59/59] 120.79.206.221 () {34 vars in 462 bytes} [Thu Mar 14 12:46:23 2019] GET / => generated 2019 bytes in 3 msecs (HTTP/1.1 404) 3 headers in 102 bytes (1 switches on core 0)
Not Found: /
[pid: 21870|app: 0|req: 60/60] 103.123.86.189 () {32 vars in 453 bytes} [Thu Mar 14 13:03:29 2019] GET / => generated 2022 bytes in 3 msecs (HTTP/1.1 404) 3 headers in 102 bytes (1 switches on core 0)
Internal Server Error: /axf/orderlist/
Traceback (most recent call last):
  File "/root/.virtualenvs/python3/lib/python3.5/site-packages/django/core/handlers/exception.py", line 41, in inner
    response = get_response(request)
  File "/root/.virtualenvs/python3/lib/python3.5/site-packages/django/core/handlers/base.py", line 187, in _get_response
    response = self.process_exception_by_middleware(e, request)
  File "/root/.virtualenvs/python3/lib/python3.5/site-packages/django/core/handlers/base.py", line 185, in _get_response
    response = wrapped_callback(request, *callback_args, **callback_kwargs)
  File "./app/views.py", line 413, in orderlist
    user = User.objects.get(pk=userid)
  File "/root/.virtualenvs/python3/lib/python3.5/site-packages/django/db/models/manager.py", line 85, in manager_method
    return getattr(self.get_queryset(), name)(*args, **kwargs)
  File "/root/.virtualenvs/python3/lib/python3.5/site-packages/django/db/models/query.py", line 380, in get
    self.model._meta.object_name
app.models.DoesNotExist: User matching query does not exist.
[pid: 21870|app: 0|req: 61/61] 106.14.168.238 () {34 vars in 509 bytes} [Thu Mar 14 13:04:56 2019] GET /axf/orderlist/ => generated 66946 bytes in 39 msecs (HTTP/1.1 500) 4 headers in 129 bytes (1 switches on core 0)
Invalid HTTP_HOST header: ''. The domain name provided is not valid according to RFC 1034/1035.
[pid: 21870|app: 0|req: 62/62] 159.192.145.195 () {26 vars in 264 bytes} [Thu Mar 14 13:21:40 2019] GET / => generated 55191 bytes in 48 msecs (HTTP/1.0 400) 1 headers in 53 bytes (1 switches on core 0)
[pid: 21870|app: 0|req: 63/63] 47.92.116.44 () {34 vars in 497 bytes} [Thu Mar 14 14:11:43 2019] GET /axf/cart/ => generated 2059 bytes in 4 msecs (HTTP/1.1 200) 4 headers in 124 bytes (1 switches on core 0)
Internal Server Error: /axf/generateorder/
Traceback (most recent call last):
  File "/root/.virtualenvs/python3/lib/python3.5/site-packages/django/core/handlers/exception.py", line 41, in inner
    response = get_response(request)
  File "/root/.virtualenvs/python3/lib/python3.5/site-packages/django/core/handlers/base.py", line 187, in _get_response
    response = self.process_exception_by_middleware(e, request)
  File "/root/.virtualenvs/python3/lib/python3.5/site-packages/django/core/handlers/base.py", line 185, in _get_response
    response = wrapped_callback(request, *callback_args, **callback_kwargs)
  File "./app/views.py", line 379, in generateorder
    user = User.objects.get(pk=userid)
  File "/root/.virtualenvs/python3/lib/python3.5/site-packages/django/db/models/manager.py", line 85, in manager_method
    return getattr(self.get_queryset(), name)(*args, **kwargs)
  File "/root/.virtualenvs/python3/lib/python3.5/site-packages/django/db/models/query.py", line 380, in get
    self.model._meta.object_name
app.models.DoesNotExist: User matching query does not exist.
[pid: 21870|app: 0|req: 64/64] 47.92.116.44 () {34 vars in 515 bytes} [Thu Mar 14 14:11:43 2019] GET /axf/generateorder/ => generated 66905 bytes in 45 msecs (HTTP/1.1 500) 4 headers in 129 bytes (1 switches on core 0)
[pid: 21870|app: 0|req: 65/65] 47.92.116.44 () {34 vars in 501 bytes} [Thu Mar 14 14:11:43 2019] GET /axf/market/ => generated 11361 bytes in 15 msecs (HTTP/1.1 200) 4 headers in 125 bytes (1 switches on core 0)
[pid: 21870|app: 0|req: 66/66] 47.92.116.44 () {34 vars in 555 bytes} [Thu Mar 14 14:11:43 2019] GET /axf/orderdetail/1552474838.9925752255/ => generated 1961 bytes in 14 msecs (HTTP/1.1 200) 3 headers in 110 bytes (1 switches on core 0)
Not Found: /
[pid: 21870|app: 0|req: 67/67] 106.14.217.247 () {34 vars in 481 bytes} [Thu Mar 14 14:17:44 2019] GET / => generated 2019 bytes in 3 msecs (HTTP/1.1 404) 3 headers in 102 bytes (1 switches on core 0)
[pid: 21870|app: 0|req: 68/68] 106.14.217.247 () {34 vars in 487 bytes} [Thu Mar 14 14:17:45 2019] GET /axf => generated 0 bytes in 0 msecs (HTTP/1.1 301) 3 headers in 110 bytes (1 switches on core 0)
[pid: 21870|app: 0|req: 69/69] 106.14.217.247 () {34 vars in 489 bytes} [Thu Mar 14 14:17:45 2019] GET /axf/ => generated 21767 bytes in 16 msecs (HTTP/1.1 200) 3 headers in 111 bytes (1 switches on core 0)
[pid: 21870|app: 0|req: 70/70] 106.14.217.247 () {34 vars in 489 bytes} [Thu Mar 14 14:17:45 2019] GET /axf/ => generated 21767 bytes in 15 msecs (HTTP/1.1 200) 3 headers in 111 bytes (1 switches on core 0)
[pid: 21870|app: 0|req: 71/71] 106.14.217.247 () {34 vars in 501 bytes} [Thu Mar 14 14:17:45 2019] GET /axf/login/ => generated 2138 bytes in 4 msecs (HTTP/1.1 200) 5 headers in 278 bytes (1 switches on core 0)
[pid: 21870|app: 0|req: 72/72] 106.14.217.247 () {34 vars in 557 bytes} [Thu Mar 14 14:17:45 2019] GET /axf/orderdetail/1552480539.0409161833/ => generated 1499 bytes in 11 msecs (HTTP/1.1 200) 3 headers in 110 bytes (1 switches on core 0)
[pid: 21870|app: 0|req: 73/73] 106.14.217.247 () {34 vars in 557 bytes} [Thu Mar 14 14:17:45 2019] GET /axf/orderdetail/1552475029.9817135518/ => generated 1684 bytes in 10 msecs (HTTP/1.1 200) 3 headers in 110 bytes (1 switches on core 0)
Not Found: /
[pid: 21870|app: 0|req: 74/74] 139.224.11.233 () {34 vars in 481 bytes} [Thu Mar 14 14:26:02 2019] GET / => generated 2019 bytes in 3 msecs (HTTP/1.1 404) 3 headers in 102 bytes (1 switches on core 0)
[pid: 21870|app: 0|req: 75/75] 139.224.11.233 () {34 vars in 499 bytes} [Thu Mar 14 14:26:02 2019] GET /axf/mine/ => generated 6232 bytes in 5 msecs (HTTP/1.1 200) 4 headers in 124 bytes (1 switches on core 0)
Internal Server Error: /axf/orderlist/
Traceback (most recent call last):
  File "/root/.virtualenvs/python3/lib/python3.5/site-packages/django/core/handlers/exception.py", line 41, in inner
    response = get_response(request)
  File "/root/.virtualenvs/python3/lib/python3.5/site-packages/django/core/handlers/base.py", line 187, in _get_response
    response = self.process_exception_by_middleware(e, request)
  File "/root/.virtualenvs/python3/lib/python3.5/site-packages/django/core/handlers/base.py", line 185, in _get_response
    response = wrapped_callback(request, *callback_args, **callback_kwargs)
  File "./app/views.py", line 413, in orderlist
    user = User.objects.get(pk=userid)
  File "/root/.virtualenvs/python3/lib/python3.5/site-packages/django/db/models/manager.py", line 85, in manager_method
    return getattr(self.get_queryset(), name)(*args, **kwargs)
  File "/root/.virtualenvs/python3/lib/python3.5/site-packages/django/db/models/query.py", line 380, in get
    self.model._meta.object_name
app.models.DoesNotExist: User matching query does not exist.
[pid: 21870|app: 0|req: 76/76] 139.224.11.233 () {34 vars in 509 bytes} [Thu Mar 14 14:26:02 2019] GET /axf/orderlist/ => generated 66946 bytes in 45 msecs (HTTP/1.1 500) 4 headers in 129 bytes (1 switches on core 0)
Not Found: /
[pid: 21870|app: 0|req: 77/77] 113.88.14.120 () {40 vars in 646 bytes} [Thu Mar 14 16:50:55 2019] GET / => generated 2019 bytes in 3 msecs (HTTP/1.1 404) 3 headers in 102 bytes (1 switches on core 0)
Not Found: /favicon.ico
[pid: 21870|app: 0|req: 78/78] 113.88.14.120 () {38 vars in 633 bytes} [Thu Mar 14 16:50:55 2019] GET /favicon.ico => generated 2070 bytes in 3 msecs (HTTP/1.1 404) 3 headers in 102 bytes (1 switches on core 0)
Not Found: /
[pid: 21870|app: 0|req: 79/79] 113.88.14.120 () {40 vars in 646 bytes} [Thu Mar 14 16:51:33 2019] GET / => generated 2019 bytes in 3 msecs (HTTP/1.1 404) 3 headers in 102 bytes (1 switches on core 0)
Not Found: /
[pid: 21870|app: 0|req: 80/80] 113.88.14.120 () {40 vars in 646 bytes} [Thu Mar 14 16:51:36 2019] GET / => generated 2019 bytes in 3 msecs (HTTP/1.1 404) 3 headers in 102 bytes (1 switches on core 0)
Not Found: /
[pid: 21870|app: 0|req: 81/81] 113.88.14.120 () {40 vars in 646 bytes} [Thu Mar 14 16:51:40 2019] GET / => generated 2019 bytes in 3 msecs (HTTP/1.1 404) 3 headers in 102 bytes (1 switches on core 0)
Not Found: /
[pid: 21870|app: 0|req: 82/82] 113.88.14.120 () {40 vars in 646 bytes} [Thu Mar 14 16:51:42 2019] GET / => generated 2019 bytes in 4 msecs (HTTP/1.1 404) 3 headers in 102 bytes (1 switches on core 0)
Not Found: /
[pid: 21870|app: 0|req: 83/83] 113.87.160.176 () {42 vars in 814 bytes} [Thu Mar 14 16:52:19 2019] GET / => generated 2019 bytes in 3 msecs (HTTP/1.1 404) 3 headers in 102 bytes (1 switches on core 0)
Not Found: /favicon.ico
[pid: 21870|app: 0|req: 84/84] 113.87.160.176 () {42 vars in 793 bytes} [Thu Mar 14 16:52:20 2019] GET /favicon.ico => generated 2070 bytes in 3 msecs (HTTP/1.1 404) 3 headers in 102 bytes (1 switches on core 0)
Not Found: /
[pid: 21870|app: 0|req: 85/85] 113.87.160.176 () {44 vars in 845 bytes} [Thu Mar 14 16:52:26 2019] GET / => generated 2019 bytes in 3 msecs (HTTP/1.1 404) 3 headers in 102 bytes (1 switches on core 0)
[pid: 21870|app: 0|req: 86/86] 113.87.160.176 () {42 vars in 822 bytes} [Thu Mar 14 16:52:43 2019] GET /axf/ => generated 21767 bytes in 17 msecs (HTTP/1.1 200) 3 headers in 111 bytes (1 switches on core 0)
[pid: 21870|app: 0|req: 87/87] 113.88.14.120 () {44 vars in 873 bytes} [Thu Mar 14 16:52:51 2019] GET /axf/mine/ => generated 6347 bytes in 11 msecs (HTTP/1.1 200) 4 headers in 124 bytes (1 switches on core 0)
[pid: 21870|app: 0|req: 88/88] 113.87.160.176 () {44 vars in 863 bytes} [Thu Mar 14 16:53:05 2019] GET /axf/mine/ => generated 6347 bytes in 16 msecs (HTTP/1.1 200) 4 headers in 124 bytes (1 switches on core 0)
[pid: 21870|app: 0|req: 89/89] 113.87.160.176 () {44 vars in 879 bytes} [Thu Mar 14 16:53:09 2019] GET /axf/cart/ => generated 2737 bytes in 11 msecs (HTTP/1.1 200) 4 headers in 124 bytes (1 switches on core 0)
[pid: 21870|app: 0|req: 90/90] 113.88.14.120 () {44 vars in 882 bytes} [Thu Mar 14 16:53:12 2019] GET /axf/market/ => generated 43231 bytes in 24 msecs (HTTP/1.1 200) 4 headers in 125 bytes (1 switches on core 0)
[pid: 21870|app: 0|req: 91/91] 113.88.14.120 () {44 vars in 831 bytes} [Thu Mar 14 16:53:15 2019] GET /axf/addcart/?goodsid=531 => generated 153 bytes in 12 msecs (HTTP/1.1 200) 4 headers in 115 bytes (1 switches on core 0)
[pid: 21870|app: 0|req: 92/92] 113.88.14.120 () {44 vars in 831 bytes} [Thu Mar 14 16:53:16 2019] GET /axf/addcart/?goodsid=532 => generated 159 bytes in 14 msecs (HTTP/1.1 200) 4 headers in 115 bytes (1 switches on core 0)
[pid: 21870|app: 0|req: 93/93] 113.88.14.120 () {44 vars in 831 bytes} [Thu Mar 14 16:53:17 2019] GET /axf/addcart/?goodsid=533 => generated 161 bytes in 12 msecs (HTTP/1.1 200) 4 headers in 115 bytes (1 switches on core 0)
[pid: 21870|app: 0|req: 94/94] 113.88.14.120 () {44 vars in 831 bytes} [Thu Mar 14 16:53:18 2019] GET /axf/addcart/?goodsid=532 => generated 159 bytes in 16 msecs (HTTP/1.1 200) 4 headers in 115 bytes (1 switches on core 0)
[pid: 21870|app: 0|req: 95/95] 113.88.14.120 () {44 vars in 831 bytes} [Thu Mar 14 16:53:19 2019] GET /axf/addcart/?goodsid=534 => generated 167 bytes in 10 msecs (HTTP/1.1 200) 4 headers in 115 bytes (1 switches on core 0)
[pid: 21870|app: 0|req: 96/96] 113.88.14.120 () {44 vars in 884 bytes} [Thu Mar 14 16:53:20 2019] GET /axf/market/ => generated 33185 bytes in 26 msecs (HTTP/1.1 200) 4 headers in 125 bytes (1 switches on core 0)
[pid: 21870|app: 0|req: 97/97] 113.88.14.120 () {44 vars in 831 bytes} [Thu Mar 14 16:53:21 2019] GET /axf/addcart/?goodsid=473 => generated 132 bytes in 11 msecs (HTTP/1.1 200) 4 headers in 115 bytes (1 switches on core 0)
[pid: 21870|app: 0|req: 98/98] 113.88.14.120 () {44 vars in 831 bytes} [Thu Mar 14 16:53:22 2019] GET /axf/addcart/?goodsid=474 => generated 124 bytes in 11 msecs (HTTP/1.1 200) 4 headers in 115 bytes (1 switches on core 0)
[pid: 21870|app: 0|req: 99/99] 113.88.14.120 () {44 vars in 831 bytes} [Thu Mar 14 16:53:22 2019] GET /axf/addcart/?goodsid=475 => generated 124 bytes in 11 msecs (HTTP/1.1 200) 4 headers in 115 bytes (1 switches on core 0)
[pid: 21870|app: 0|req: 100/100] 113.88.14.120 () {44 vars in 880 bytes} [Thu Mar 14 16:53:23 2019] GET /axf/cart/ => generated 8753 bytes in 22 msecs (HTTP/1.1 200) 4 headers in 124 bytes (1 switches on core 0)
[pid: 21870|app: 0|req: 101/101] 113.88.14.120 () {44 vars in 841 bytes} [Thu Mar 14 16:53:25 2019] GET /axf/changecartall/?isall=false => generated 74 bytes in 36 msecs (HTTP/1.1 200) 4 headers in 114 bytes (1 switches on core 0)
[pid: 21870|app: 0|req: 102/102] 113.88.14.120 () {44 vars in 843 bytes} [Thu Mar 14 16:53:27 2019] GET /axf/changecartselect/?cartid=27 => generated 78 bytes in 7 msecs (HTTP/1.1 200) 3 headers in 100 bytes (1 switches on core 0)
[pid: 21870|app: 0|req: 103/103] 113.88.14.120 () {44 vars in 843 bytes} [Thu Mar 14 16:53:28 2019] GET /axf/changecartselect/?cartid=26 => generated 78 bytes in 7 msecs (HTTP/1.1 200) 3 headers in 100 bytes (1 switches on core 0)
[pid: 21870|app: 0|req: 104/104] 113.88.14.120 () {44 vars in 843 bytes} [Thu Mar 14 16:53:31 2019] GET /axf/changecartselect/?cartid=29 => generated 78 bytes in 8 msecs (HTTP/1.1 200) 3 headers in 100 bytes (1 switches on core 0)
[pid: 21870|app: 0|req: 105/105] 113.88.14.120 () {44 vars in 843 bytes} [Thu Mar 14 16:53:32 2019] GET /axf/changecartselect/?cartid=28 => generated 78 bytes in 7 msecs (HTTP/1.1 200) 3 headers in 100 bytes (1 switches on core 0)
[pid: 21870|app: 0|req: 106/106] 113.88.14.120 () {44 vars in 843 bytes} [Thu Mar 14 16:53:34 2019] GET /axf/changecartselect/?cartid=26 => generated 79 bytes in 9 msecs (HTTP/1.1 200) 3 headers in 100 bytes (1 switches on core 0)
[pid: 21870|app: 0|req: 107/107] 113.88.14.120 () {44 vars in 843 bytes} [Thu Mar 14 16:53:35 2019] GET /axf/changecartselect/?cartid=27 => generated 79 bytes in 7 msecs (HTTP/1.1 200) 3 headers in 100 bytes (1 switches on core 0)
[pid: 21870|app: 0|req: 108/108] 113.88.14.120 () {44 vars in 843 bytes} [Thu Mar 14 16:53:37 2019] GET /axf/changecartselect/?cartid=27 => generated 78 bytes in 7 msecs (HTTP/1.1 200) 3 headers in 100 bytes (1 switches on core 0)
[pid: 21870|app: 0|req: 109/109] 113.88.14.120 () {44 vars in 843 bytes} [Thu Mar 14 16:53:38 2019] GET /axf/changecartselect/?cartid=27 => generated 79 bytes in 9 msecs (HTTP/1.1 200) 3 headers in 100 bytes (1 switches on core 0)
[pid: 21870|app: 0|req: 110/110] 113.88.14.120 () {44 vars in 843 bytes} [Thu Mar 14 16:53:38 2019] GET /axf/changecartselect/?cartid=27 => generated 78 bytes in 7 msecs (HTTP/1.1 200) 3 headers in 100 bytes (1 switches on core 0)
[pid: 21870|app: 0|req: 111/111] 113.88.14.120 () {44 vars in 843 bytes} [Thu Mar 14 16:53:39 2019] GET /axf/changecartselect/?cartid=27 => generated 79 bytes in 7 msecs (HTTP/1.1 200) 3 headers in 100 bytes (1 switches on core 0)
[pid: 21870|app: 0|req: 112/112] 113.88.14.120 () {44 vars in 843 bytes} [Thu Mar 14 16:53:40 2019] GET /axf/changecartselect/?cartid=27 => generated 78 bytes in 7 msecs (HTTP/1.1 200) 3 headers in 100 bytes (1 switches on core 0)
[pid: 21870|app: 0|req: 113/113] 113.88.14.120 () {44 vars in 843 bytes} [Thu Mar 14 16:53:41 2019] GET /axf/changecartselect/?cartid=27 => generated 79 bytes in 7 msecs (HTTP/1.1 200) 3 headers in 100 bytes (1 switches on core 0)
[pid: 21870|app: 0|req: 114/114] 113.88.14.120 () {44 vars in 843 bytes} [Thu Mar 14 16:53:42 2019] GET /axf/changecartselect/?cartid=27 => generated 78 bytes in 10 msecs (HTTP/1.1 200) 3 headers in 100 bytes (1 switches on core 0)
[pid: 21870|app: 0|req: 115/115] 113.88.14.120 () {44 vars in 843 bytes} [Thu Mar 14 16:53:45 2019] GET /axf/changecartselect/?cartid=27 => generated 79 bytes in 7 msecs (HTTP/1.1 200) 3 headers in 100 bytes (1 switches on core 0)
[pid: 21870|app: 0|req: 116/116] 113.88.14.120 () {44 vars in 843 bytes} [Thu Mar 14 16:53:47 2019] GET /axf/changecartselect/?cartid=28 => generated 79 bytes in 7 msecs (HTTP/1.1 200) 3 headers in 100 bytes (1 switches on core 0)
[pid: 21870|app: 0|req: 117/117] 113.88.14.120 () {44 vars in 843 bytes} [Thu Mar 14 16:53:49 2019] GET /axf/changecartselect/?cartid=29 => generated 79 bytes in 7 msecs (HTTP/1.1 200) 3 headers in 100 bytes (1 switches on core 0)
[pid: 21870|app: 0|req: 118/118] 113.88.14.120 () {44 vars in 843 bytes} [Thu Mar 14 16:53:52 2019] GET /axf/changecartselect/?cartid=26 => generated 78 bytes in 7 msecs (HTTP/1.1 200) 3 headers in 100 bytes (1 switches on core 0)
[pid: 21870|app: 0|req: 119/119] 113.88.14.120 () {44 vars in 843 bytes} [Thu Mar 14 16:53:54 2019] GET /axf/changecartselect/?cartid=27 => generated 78 bytes in 7 msecs (HTTP/1.1 200) 3 headers in 100 bytes (1 switches on core 0)
[pid: 21870|app: 0|req: 120/120] 113.88.14.120 () {44 vars in 843 bytes} [Thu Mar 14 16:53:55 2019] GET /axf/changecartselect/?cartid=27 => generated 79 bytes in 7 msecs (HTTP/1.1 200) 3 headers in 100 bytes (1 switches on core 0)
[pid: 21870|app: 0|req: 121/121] 113.88.14.120 () {44 vars in 843 bytes} [Thu Mar 14 16:53:56 2019] GET /axf/changecartselect/?cartid=27 => generated 78 bytes in 7 msecs (HTTP/1.1 200) 3 headers in 100 bytes (1 switches on core 0)
[pid: 21870|app: 0|req: 122/122] 113.88.14.120 () {44 vars in 843 bytes} [Thu Mar 14 16:53:57 2019] GET /axf/changecartselect/?cartid=27 => generated 79 bytes in 7 msecs (HTTP/1.1 200) 3 headers in 100 bytes (1 switches on core 0)
[pid: 21870|app: 0|req: 123/123] 113.88.14.120 () {44 vars in 843 bytes} [Thu Mar 14 16:53:58 2019] GET /axf/changecartselect/?cartid=27 => generated 78 bytes in 12 msecs (HTTP/1.1 200) 3 headers in 100 bytes (1 switches on core 0)
[pid: 21870|app: 0|req: 124/124] 113.88.14.120 () {44 vars in 843 bytes} [Thu Mar 14 16:53:58 2019] GET /axf/changecartselect/?cartid=27 => generated 79 bytes in 8 msecs (HTTP/1.1 200) 3 headers in 100 bytes (1 switches on core 0)
[pid: 21870|app: 0|req: 125/125] 113.88.14.120 () {44 vars in 843 bytes} [Thu Mar 14 16:54:08 2019] GET /axf/changecartselect/?cartid=27 => generated 78 bytes in 13 msecs (HTTP/1.1 200) 3 headers in 100 bytes (1 switches on core 0)
[pid: 21870|app: 0|req: 126/126] 113.88.14.120 () {44 vars in 843 bytes} [Thu Mar 14 16:54:08 2019] GET /axf/changecartselect/?cartid=27 => generated 79 bytes in 7 msecs (HTTP/1.1 200) 3 headers in 100 bytes (1 switches on core 0)
[pid: 21870|app: 0|req: 127/127] 113.88.14.120 () {44 vars in 896 bytes} [Thu Mar 14 16:54:14 2019] GET /axf/generateorder/ => generated 1329 bytes in 25 msecs (HTTP/1.1 200) 4 headers in 124 bytes (1 switches on core 0)
Not Found: /
[pid: 21870|app: 0|req: 128/128] 195.154.61.206 () {34 vars in 501 bytes} [Thu Mar 14 16:58:28 2019] GET / => generated 2019 bytes in 3 msecs (HTTP/1.1 404) 3 headers in 102 bytes (1 switches on core 0)
[pid: 21870|app: 0|req: 129/129] 113.87.160.176 () {44 vars in 881 bytes} [Thu Mar 14 17:08:10 2019] GET /axf/generateorder/ => generated 1164 bytes in 15 msecs (HTTP/1.1 200) 4 headers in 124 bytes (1 switches on core 0)
[pid: 21870|app: 0|req: 130/130] 113.87.160.176 () {44 vars in 881 bytes} [Thu Mar 14 17:08:13 2019] GET /axf/generateorder/ => generated 1163 bytes in 14 msecs (HTTP/1.1 200) 4 headers in 124 bytes (1 switches on core 0)
[pid: 21870|app: 0|req: 131/131] 113.87.160.176 () {44 vars in 881 bytes} [Thu Mar 14 17:08:15 2019] GET /axf/generateorder/ => generated 1164 bytes in 13 msecs (HTTP/1.1 200) 4 headers in 124 bytes (1 switches on core 0)
[pid: 21870|app: 0|req: 132/132] 113.88.14.120 () {44 vars in 880 bytes} [Thu Mar 14 17:20:21 2019] GET /axf/generateorder/ => generated 1164 bytes in 16 msecs (HTTP/1.1 200) 4 headers in 124 bytes (1 switches on core 0)
Not Found: /
[pid: 21870|app: 0|req: 133/133] 177.12.241.60 () {32 vars in 446 bytes} [Thu Mar 14 17:23:03 2019] GET / => generated 2022 bytes in 4 msecs (HTTP/1.1 404) 3 headers in 102 bytes (1 switches on core 0)
Not Found: /
[pid: 21870|app: 0|req: 134/134] 91.108.214.190 () {36 vars in 503 bytes} [Thu Mar 14 17:24:56 2019] GET / => generated 2019 bytes in 3 msecs (HTTP/1.1 404) 3 headers in 102 bytes (1 switches on core 0)
Not Found: /axf/appnotifyurl/
[pid: 21870|app: 0|req: 135/135] 113.87.160.176 () {40 vars in 681 bytes} [Thu Mar 14 17:53:26 2019] GET /axf/appnotifyurl/ => generated 4921 bytes in 5 msecs (HTTP/1.1 404) 3 headers in 102 bytes (1 switches on core 0)
Not Found: /favicon.ico
[pid: 21870|app: 0|req: 136/136] 113.87.160.176 () {38 vars in 634 bytes} [Thu Mar 14 17:53:26 2019] GET /favicon.ico => generated 2070 bytes in 3 msecs (HTTP/1.1 404) 3 headers in 102 bytes (1 switches on core 0)
